Workbook
Name NewHoldingValue: #REF!
Name NewPortfolioPercent: #REF!
Name PortfolioPercent: 'Copy of Holdings'!$I$3:$I$20
Name HoldingValue: 'Copy of Holdings 1'!$H$3:$H$20
Name TotalValue: 'Copy of Holdings 1'!$H$21
Name StocksValue: 'Copy of Stocks'!$H$5:$H$12
Name NewHoldingValue: #REF!
Name TotalValue: 'Copy of Holdings'!$H$21
Name TotalStockValue: 'Copy of Stocks'!$H$13
Name NewPortfolioPercent: #REF!
Name NewTotalValue: #REF!
Name NewTotalValue: #REF!
Name PortfolioPercent: 'Copy of Holdings 1'!$I$3:$I$20
Name HoldingValue: 'Copy of Holdings'!$H$3:$H$20

Sheet 2018
A1: Payment Schedule 2018
A2: Schedule | B2: Week 1 | C2: Week 2 | D2: REMAINING BALANCE | E2: TOTAL SAVINGS | F2: TOTAL DEBT
A3: Starting Balance | B3: 0 | C3: =B12 | D3: 0 | E3: =D27+B7+C7 -> 0 | F3: =#REF!-B8-C8 -> #REF!
A4: Income #1 | B4: 2500 | C4: 1850
A5: Additional Income | B5: 1900 | C5: 0
A6: EXPENSES | B6: =#REF! -> #REF! | C6: 250
A7: SAVINGS | B7: =B27 | C7: =C27
A8: DEBTS MANAGEMENT | B8: =#REF! -> #REF! | C8: =#REF! -> #REF!
A9: PERSONAL EXPENSES | B9: =B22 -> 610 | C9: =C22 -> 800
A10: BUSINESS EXPENSES | B10: =#REF!-#REF! -> #REF! | C10: =#REF!-#REF! -> #REF!
A11: NON-PROFIT | B11: =#REF! -> #REF! | C11: 50
A12: Net
A14: PERSONAL EXPENSES | B14: WEEK 1 | C14: WEEK 2 | D14: TOTAL | E14: STATUS | F14: SCHEDULE
A15: Groceries | B15: 100 | C15: 100 | E15: ACTIVE
A16: Restaurants & Bars | B16: 200 | C16: 200 | E16: ACTIVE
A17: Services | B17: 10 | C17: 0 | E17: ACTIVE | F17: Spotify, Nomad List
A18: Travel (Hosting, Flights) | B18: 200 | C18: 400 | E18: PAUSED
A19: Clothing | B19: 100 | C19: 100 | E19: PAUSED
A20: Healthcare | B20: 0 | C20: 0 | E20: PAUSED
A21: Misc. | B21: 0 | C21: 0 | E21: PAUSED
A22: TOTAL | B22: =sum(B15:B21) -> 610 | C22: =sum(C15:C21) -> 800
A24: SAVINGS | B24: WEEK 1 | C24: WEEK 2 | D24: TOTAL | E24: STATUS | F24: SCHEDULE
A25: Travel (Simple) | B25: 0 | C25: 0 | D25: 0 | E25: ACTIVE
A26: Rainy Day (Simple) | B26: 100 | C26: 0 | D26: 100 | E26: ACTIVE
A27: TOTAL
A29: INVEST | B29: WEEK 1 | C29: WEEK 2 | D29: TOTAL | E29: STATUS | F29: SCHEDULE
A30: Hashtag Language | B30: 100 | C30: 100 | D30: 1612 | E30: ACTIVE
A31: Roth IRA | B31: 100 | C31: 100 | D31: 300 | E31: ACTIVE
A32: Ethereum | B32: 100 | C32: 0 | D32: 0 | E32: ACTIVE
A33: Bitcoin | B33: 0 | C33: 0 | D33: 0.01843329 | E33: ACTIVE
A34: EOS | B34: 0 | C34: 0 | D34: 0 | E34: PAUSED
A35: XRP | B35: 0 | C35: 0 | D35: 300 | E35: PAUSED
A36: NEO | B36: 0 | C36: 0 | D36: 0 | E36: PAUSED | F36: *Hold for Nancy
A37: DCR | B37: 0 | C37: 0 | D37: 0 | E37: PAUSED
A38: XLM | B38: 0 | C38: 0 | D38: 0 | E38: PAUSED
A39: ETrade | B39: 0 | C39: 0 | D39: 0 | E39: PAUSED | F39: TSLA, AMZN, FB
A41: DEBTS | B41: WEEK 1 | C41: WEEK 2 | D41: TOTAL | E41: STATUS | F41: SCHEDULE
A42: Capital One | B42: 250 | C42: 250 | D42: 500 | E42: ACTIVE | F42: 1st, 15th
A43: Wells Fargo | B43: 200 | C43: 200 | D43: 2800 | E43: ACTIVE | F43: 1st, 15th (15 Payments~12/1/2017)
A44: NuVision | B44: 50 | C44: 50 | D44: 350 | E44: ACTIVE | F44: 1st (7 Payments~12/1/2017)
...

Sheet DASHBOARD
B1: DASHBOARD
B2: =AVERAGE(BUDGET!AM13:AX13) -> 16241.259 | C2: =HOLDINGS!C52 -> 12251244 | D2: 675 | E2: 0.4 | F2: =LIABILITIES!C41 -> 25401.63 | G2: XXXX
B3: Avg. Monthly Net | C3: Net worth | D3: Credit Score | E3: Credit Usage | F3: Debt | G3: xxxx
B22: Goals:
B23: - $350k salary
B24: - Exercise $8k CSI shares
B25: - Pay $50k liabilities | C25: (Upstart, Sapphire priorities, lower spending 50%)
B26: - $30k to invest into seed
B27: - Purchase Jaeger LeCouture
B28: - $20k in ETH, $20k in BTC
B29: - $30k cash savings (75% in high yield) | D29: Amount Needed | E29: Due
B30: - 800 credit score | D30: 82631 | E30: 45778 | F30: Consensys Shares
B31: - $10k in IRA, Stocks | D31: 15000 | F31: Bitcoin
D32: 35000 | F32: Ethereum
D33: 10000 | F33: Stock, IRA
D34: 30000 | F34: Savings
D36: =sum(D30:D34) -> 172631

Sheet BUDGET
A1: Categories | C1: Jan | D1: Feb | E1: Mar | F1: Apr | G1: May | H1: Jun | I1: Jul '19 | J1: Aug '19 | K1: Sept '19 | L1: Oct '19 | M1: Nov '19 | N1: Dec '19 | O1: Jan '20 | P1: Feb '20 | Q1: Mar '20 | R1: Apr '20 | S1: May '20 | T1: Jun '20 | U1: Jul '20 | V1: Aug '20 | W1: Sep '20 | X1: Oct '20 | Y1: Nov '20 | Z1: Dec '20 | AA1: Jan '21 | AB1: Feb'21 | AC1: Mar '21 | AD1: Apr '21 | AE1: May '21 | AF1: Jun '21 | AG1: Jul '21 | AH1: Aug '21 | AI1: Sept '21 | AJ1: Oct '21 | AK1: Nov '21 | AL1: Dec '21 | AM1: Jan '22 | AN1: Feb '22 | AO1: Mar '22 | AP1: Apr '22 | AQ1: May '22 | AR1: Jun '22 | AS1: July '22 | AT1: Aug '22 | AU1: Sept '22 | AV1: Oct '22 | AW1: Nov '22 | AX1: Dec '22 | AY1: Jan '23 | AZ1: Feb '23 | BA1: Mar '23 | BB1: Apr '23 | BC1: May '23 | BD1: Jun '23 | BE1: Jul '23 | BF1: Aug '23 | BG1: Sept '23 | BH1: Oct '23 | BI1: Nov '23 | BJ1: Dec '23 | BK1: FY 2023 | BL1: Jan '24 | BM1: Feb '24 | BN1: Mar '24 | BO1: Apr '24 | BP1: May '24 | BQ1: Jun '24 | BR1: Jul '24 | BS1: Aug '24 | BT1: Sep '24 | BU1: Oct '24 | BV1: Nov '24 | BW1: Dec '24 | BX1: FY 2024 | BY1: Jan '25 | BZ1: Feb '25 | CA1: Mar '25 | CB1: Apr '25 | CC1: May '25 | CD1: Jun '25 | CE1: Jul '25 | CF1: Aug '25 | CG1: Sep '25 | CH1: Oct '25 | CI1: Nov '25 | CJ1: Dec '25 | CK1: FY 2025 | CL1: Jan '26 | CM1: Feb '26 | CN1: Mar '26 | CO1: Apr '26 | CP1: May '26 | CQ1: Jun '26 | CR1: Jul '26 | CS1: Aug '26 | CT1: Sep '26 | CU1: Oct '26 | CV1: Nov '26 | CW1: Dec '26 | CX1: FY 2026 | CY1: Nov '25 | CZ1: Dec '25
A2: Income
A3: Salary
B4: Salary (Pre-Tax of 34%) | C4: 10000 | D4: 10000 | E4: 10000 | F4: 10000 | G4: 10000 | H4: 10000 | I4: 10000 | J4: =120000/12 -> 10000 | K4: =120000/12 -> 10000 | L4: =120000/12 -> 10000 | M4: =120000/12 -> 10000 | N4: =120000/12 -> 10000 | O4: =120000/12 -> 10000 | P4: =120000/12 -> 10000 | Q4: =123000/12 -> 10250 | R4: =123000/12 -> 10250 | S4: =123000/12 -> 10250 | T4: =123000/12 -> 10250 | U4: =123000/12 -> 10250 | V4: =123000/12 -> 10250 | W4: =123000/12 -> 10250 | X4: =123000/12 -> 10250 | Y4: =123000/12 -> 10250 | Z4: =160000/12 -> 13333.333 | AA4: =160000/12 -> 13333.333 | AB4: =160000/12 -> 13333.333 | AC4: =160000/12 -> 13333.333 | AD4: =160000/12 -> 13333.333 | AE4: =160000/12 -> 13333.333 | AF4: =160000/12 -> 13333.333 | AG4: =160000/12 -> 13333.333 | ... AJ4: =160000/12 -> 13333.333 | AK4: =165000/12 -> 13750 | AL4: =210000/12 -> 17500 | AM4: =210000/12 -> 17500 | AN4: =210000/12 -> 17500 | AO4: =210000/12 -> 17500 | AP4: =210000/12 -> 17500 | AQ4: =210000/12 -> 17500 | AR4: =210000/12 -> 17500 | AS4: =210000/12 -> 17500 | ... AZ4: =210000/12 -> 17500 | BA4: =200000/12 -> 16666.667 | BB4: =200000/12 -> 16666.667 | BC4: =200000/12 -> 16666.667 | BD4: =200000/12 -> 16666.667 | BE4: =200000/12 -> 16666.667 | BF4: =220000/12 -> 18333.333 | BG4: =220000/12 -> 18333.333 | BH4: =220000/12 -> 18333.333 | BI4: =220000/12 -> 18333.333 | BJ4: =220000/12 -> 18333.333 | BL4: =220000/12 -> 18333.333 | BM4: =220000/12 -> 18333.333 | BN4: =220000/12 -> 18333.333 | BO4: =220000/12 -> 18333.333 | BP4: =220000/12 -> 18333.333 | BQ4: =220000/12 -> 18333.333 | BR4: =220000/12 -> 18333.333 | BS4: =220000/12 -> 18333.333 | ... BW4: =220000/12 -> 18333.333 | BX4: =sum(BL4:BW4) -> 220000 | BY4: =220000/12 -> 18333.333 | BZ4: =220000/12 -> 18333.333 | CA4: =220000/12 -> 18333.333 | CB4: =220000/12 -> 18333.333 | CC4: =360000/12 -> 30000 | CD4: =360000/12 -> 30000 | CE4: =360000/12 -> 30000 | CF4: =360000/12 -> 30000 | CG4: =360000/12 -> 30000 | CH4: =360000/12 -> 30000 | CI4: =360000/12 -> 30000 | CJ4: =360000/12 -> 30000 | CK4: =sum(BY4:CJ4) -> 313333.33 | CL4: =220000/12 -> 18333.333 | CM4: =220000/12 -> 18333.333 | CN4: =220000/12 -> 18333.333 | CO4: =360000/12 -> 30000 | CP4: =360000/12 -> 30000 | CQ4: =360000/12 -> 30000 | CR4: =360000/12 -> 30000 | CS4: =360000/12 -> 30000 | CT4: =360000/12 -> 30000 | CU4: =360000/12 -> 30000 | CV4: =360000/12 -> 30000 | CW4: =360000/12 -> 30000 | CX4: =sum(CL4:CW4) -> 325000 | CY4: =400000/12 -> 33333.333 | CZ4: =400000/12 -> 33333.333
B5: Freelance (Taxed at 41%) | C5: 0 | D5: 3000 | E5: 0 | F5: 0 | G5: 0 | H5: 0 | I5: 5000 | J5: 5000 | K5: 0 | L5: 0 | M5: 800 | N5: =500 -> 500 | O5: 0 | P5: =5000 -> 5000 | Q5: 0 | R5: 0 | S5: 0 | T5: 0 | U5: 0 | V5: 0 | W5: 0 | X5: 0 | Y5: 0 | Z5: 0 | AA5: 0 | AB5: 0 | AC5: 0 | AD5: 0 | AE5: 0 | AF5: 0 | AG5: 0 | AH5: 0 | AI5: 0 | AJ5: 0 | AK5: 0 | AL5: 0 | AM5: 0 | AN5: 0 | AO5: 0 | AP5: 0 | AQ5: 0 | AR5: 0 | AS5: 0 | AT5: 0 | AU5: 0 | AV5: 0 | AW5: 0 | AX5: 0 | AY5: 0 | AZ5: 0 | BA5: 0 | BB5: 0 | BC5: 0 | BD5: 0 | BE5: 0 | BF5: 0 | BG5: 0 | BH5: 0 | BI5: 0 | BJ5: 0 | BL5: 0 | BM5: 0 | BN5: 0 | BO5: 0 | BP5: 0 | BQ5: 0 | BR5: 0 | BS5: 0 | BT5: 0 | BU5: 0 | BV5: 0 | BW5: 0 | BX5: =sum(BL5:BW5) -> 0 | BY5: 0 | BZ5: 0 | CA5: 0 | CB5: 0 | CC5: 0 | CD5: 0 | CE5: 0 | CF5: 0 | CG5: 0 | CH5: 0 | CI5: 0 | CJ5: 0 | CK5: =sum(BY5:CJ5) -> 0 | CL5: 0 | CM5: 0 | CN5: 0 | CO5: 0 | CP5: 0 | CQ5: 0 | CR5: 0 | CS5: 0 | CT5: 0 | CU5: 0 | CV5: 0 | CW5: 0 | CX5: =sum(CL5:CW5) -> 0 | CY5: 0 | CZ5: 0
A6: Freelance
B7: Secondary Income (Taxed @ 34%) | C7: 0 | D7: 0 | E7: 0 | F7: 0 | G7: 0 | H7: 0 | I7: 0 | J7: 0 | K7: 0 | L7: 0 | M7: 0 | N7: 0 | O7: 0 | P7: 0 | Q7: 0 | R7: 0 | S7: 0 | T7: =S7+S7*0.15 -> 0 | U7: =T7+T7*0.15 -> 0 | V7: =U7+U7*0.15 -> 0 | W7: =V7+V7*0.15 -> 0 | X7: 0 | Y7: 0 | Z7: =Y7+Y7*0.1 -> 0 | AA7: =Z7+Z7*0.1 -> 0 | AB7: =AA7+AA7*0.1 -> 0 | AC7: =AB7+AB7*0.1 -> 0 | AD7: =AC7+AC7*0.1 -> 0 | AE7: =AD7+AD7*0.1 -> 0 | AF7: =AE7+AE7*0.1 -> 0 | AG7: =AF7+AF7*0.1 -> 0 | AH7: =AG7+AG7*0.1 -> 0 | AI7: =AG7+AG7*0.1 -> 0 | AJ7: =AH7+AH7*0.1 -> 0 | AK7: =AJ7+AJ7*0.1 -> 0 | AL7: =AK7+AK7*0.1 -> 0 | AM7: =AL7+AL7*0.1 -> 0 | AN7: =AM7+AM7*0.1 -> 0 | AO7: =AN7+AN7*0.1 -> 0 | AP7: =AO7+AO7*0.1 -> 0 | AQ7: =AP7+AP7*0.1 -> 0 | AR7: =AQ7+AQ7*0.1 -> 0 | ... AT7: =AS7+AS7*0.1 -> 0 | AU7: 0 | AV7: 0 | AW7: 0 | AX7: 0 | AY7: 0 | AZ7: 0 | BA7: 0 | BB7: 0 | BC7: 0 | BD7: 0 | BE7: 0 | BF7: 60000 | BG7: 0 | BH7: 0 | BI7: 0 | BJ7: 0 | BL7: 0 | BM7: 0 | BN7: 0 | BO7: 0 | BP7: 0 | BQ7: 0 | BR7: 0 | BS7: 0 | BT7: 0 | BU7: 0 | BV7: 0 | BW7: 0 | BX7: =sum(BL7:BW7) -> 0 | BY7: 0 | BZ7: 0 | CA7: 0 | CB7: 0 | CC7: 0 | CD7: 0 | CE7: 5000000 | CF7: 5000000 | CG7: 5000000 | CH7: 5000000 | CI7: 0 | CJ7: 0 | CK7: =sum(BY7:CJ7) -> 20000000 | CL7: 0 | CM7: 0 | CN7: 0 | CO7: 0 | CP7: 0 | CQ7: 0 | CR7: 0 | CS7: 0 | CT7: 0 | CU7: 0 | CV7: 0 | CW7: 0 | CX7: =sum(CL7:CW7) -> 0 | CY7: 0 | CZ7: 0
B8: Non-taxed Income | O8: =1000 -> 1000 | P8: =2723 -> 2723 | Q8: 419 | R8: =200 -> 200 | S8: =900+2500 -> 3400 | T8: 0 | U8: 0 | V8: 300 | W8: 0 | X8: 0 | Y8: 5600 | Z8: 0 | AA8: 0 | AB8: 0 | AC8: 700 | AD8: 0 | AE8: 11000 | AF8: 1300 | AG8: =sum(1200,1200) -> 2400 | AH8: =sum(7000,10000) -> 17000 | AI8: 0 | AJ8: 0 | AK8: =2000+7700 -> 9700 | AL8: 0 | AM8: 0 | AN8: 10000 | AO8: 1000 | AP8: 21000 | AQ8: 0 | AR8: 0 | AS8: 0 | AT8: =sum(4751.11) -> 4751.11 | AU8: =36000*0.45 -> 16200 | AV8: 0 | AW8: 0 | AX8: =SUM(1500,1844) -> 3344 | AY8: =sum(1000,1800) -> 2800 | AZ8: 16000 | BA8: 20000 | BB8: 0 | BC8: 2500 | BD8: 0 | BE8: 0 | BF8: =sum(-2000,-3000,-1200) -> -6200 | BG8: =sum(5000,2000) -> 7000 | BH8: =sum(10000,1000) -> 11000 | BI8: 0 | BJ8: 0 | BL8: 30000 | BM8: 10000 | BN8: =sum(25000) -> 25000 | BO8: =sum(24000) -> 24000 | BP8: 2000 | BQ8: =sum(20000) -> 20000 | BR8: =sum(50000) -> 50000 | BS8: =SUM(2800,6000) -> 8800 | BT8: 10000 | BU8: 0 | BV8: 0 | BW8: =sum(10000) -> 10000 | BX8: =sum(BL8:BW8) -> 189800 | BY8: =sum(10000) -> 10000 | BZ8: =sum(10000) -> 10000 | CA8: =sum(85000) -> 85000 | CB8: =sum(7500,11000,75000) -> 93500 | CC8: 0 | CD8: 250000 | CE8: 0 | CF8: 0 | CG8: 0 | CH8: 0 | CI8: 0 | CJ8: 0 | CK8: =sum(BY8:CJ8) -> 448500 | CL8: =sum(10000) -> 10000 | CM8: =sum(10000) -> 10000 | CN8: =sum(7500,11000,10000) -> 28500 | CO8: 200000 | CP8: 0 | CQ8: 0 | CR8: 0 | CS8: 0 | CT8: 0 | CU8: 0 | CV8: 0 | CW8: 0 | CX8: =sum(CL8:CW8) -> 248500 | CY8: 0 | CZ8: 0
A10: Total Income | C10: =sum(C4:C7) -> 10000 | D10: =sum(D4:D7) -> 13000 | E10: =sum(E4:E7) -> 10000 | F10: =sum(F4:F7) -> 10000 | G10: =sum(G4:G7) -> 10000 | H10: =sum(H4:H7) -> 10000 | I10: =sum(I4:I7) -> 15000 | J10: =sum(J4:J7) -> 15000 | ... O10: =sum(O4:O7) -> 10000 | P10: =sum(P4:P8) -> 17723 | Q10: =sum(Q4:Q8) -> 10669 | R10: =sum(R4:R8) -> 10450 | S10: =sum(S4:S8) -> 13650 | T10: =sum(T4:T8) -> 10250 | U10: =sum(U4:U8) -> 10250 | V10: =sum(V4:V8) -> 10550 | W10: =sum(W4:W8) -> 10250 | ... BJ10: =sum(BJ4:BJ8) -> 18333.333 | BL10: =sum(BL4:BL8) -> 48333.333 | BM10: =sum(BM4:BM8) -> 28333.333 | BN10: =sum(BN4:BN8) -> 43333.333 | BO10: =sum(BO4:BO8) -> 42333.333 | BP10: =sum(BP4:BP8) -> 20333.333 | BQ10: =sum(BQ4:BQ8) -> 38333.333 | BR10: =sum(BR4:BR8) -> 68333.333 | BS10: =sum(BS4:BS8) -> 27133.333 | ... BW10: =sum(BW4:BW8) -> 28333.333 | BX10: =sum(BL10:BW10) -> 409800 | BY10: =sum(BY4:BY8) -> 28333.333 | BZ10: =sum(BZ4:BZ8) -> 28333.333 | CA10: =sum(CA4:CA8) -> 103333.33 | CB10: =sum(CB4:CB8) -> 111833.33 | CC10: =sum(CC4:CC8) -> 30000 | CD10: =sum(CD4:CD8) -> 280000 | CE10: =sum(CE4:CE8) -> 5030000 | CF10: =sum(CF4:CF8) -> 5030000 | ... CJ10: =sum(CJ4:CJ8) -> 30000 | CK10: =sum(BY10:CJ10) -> 20761833 | CL10: =sum(CL4:CL8) -> 28333.333 | CM10: =sum(CM4:CM8) -> 28333.333 | CN10: =sum(CN4:CN8) -> 46833.333 | CO10: =sum(CO4:CO8) -> 230000 | CP10: =sum(CP4:CP8) -> 30000 | CQ10: =sum(CQ4:CQ8) -> 30000 | CR10: =sum(CR4:CR8) -> 30000 | CS10: =sum(CS4:CS8) -> 30000 | ... CW10: =sum(CW4:CW8) -> 30000 | CX10: =sum(CL10:CW10) -> 573500 | CY10: =sum(CY4:CY8) -> 33333.333 | CZ10: =sum(CZ4:CZ8) -> 33333.333
A11: Tax + Withholding | C11: =C10*0.38 -> 3800 | D11: =D10*0.34 -> 4420 | E11: =E10*0.34 -> 3400 | F11: =F10*0.34 -> 3400 | G11: =G10*0.34 -> 3400 | H11: =H10*0.34 -> 3400 | I11: =I10*0.34 -> 5100 | J11: =J10*0.34 -> 5100 | K11: =K10*0.34 -> 3400 | L11: =L10*0.34 -> 3400 | M11: =sum(M4:M7)*0.34 -> 3672 | N11: =sum(N4:N7)*0.34 -> 3570 | O11: =sum(O4:O7)*0.34+O5*0.41 -> 3400 | P11: =P4*0.34+P5*0.41+P7*0.34 -> 5450 | Q11: =sum(Q4:Q7)*0.34+Q5*0.41 -> 3485 | R11: =sum(R4:R7)*0.34+R5*0.41 -> 3485 | S11: =sum(S4:S7)*0.34+S5*0.41 -> 3485 | T11: =sum(T4:T7)*0.34+T5*0.41 -> 3485 | U11: =sum(U4:U7)*0.34+U5*0.41 -> 3485 | V11: =sum(V4:V7)*0.34+V5*0.41 -> 3485 | W11: =sum(W4:W7)*0.34+W5*0.41 -> 3485 | X11: =sum(X4:X7)*0.34+X5*0.41 -> 3485 | ... BE11: =sum(BE4:BE7)*0.34+BE5*0.41 -> 5666.6667 | BF11: =sum(BF4:BF7)*0.34+BF5*0.52 -> 26633.333 | BG11: =sum(BG4:BG7)*0.34+BG5*0.41 -> 6233.3333 | BH11: =sum(BH4:BH7)*0.34+BH5*0.41 -> 6233.3333 | BI11: =sum(BI4:BI7)*0.34+BI5*0.41 -> 6233.3333 | BJ11: =sum(BJ4:BJ7)*0.34+BJ5*0.41 -> 6233.3333 | BL11: =sum(BL4:BL7)*0.34+BL5*0.41 -> 6233.3333 | BM11: =sum(BM4:BM7)*0.34+BM5*0.41 -> 6233.3333 | BN11: =sum(BN4:BN7)*0.34+BN5*0.41 -> 6233.3333 | BO11: =sum(BO4:BO7)*0.34+BO5*0.41 -> 6233.3333 | BP11: =sum(BP4:BP7)*0.34+BP5*0.41 -> 6233.3333 | BQ11: =sum(BQ4:BQ7)*0.34+BQ5*0.41 -> 6233.3333 | BR11: =sum(BR4:BR7)*0.34+BR5*0.41 -> 6233.3333 | BS11: =sum(BS4:BS7)*0.34+BS5*0.41 -> 6233.3333 | ... BW11: =sum(BW4:BW7)*0.34+BW5*0.41 -> 6233.3333 | BX11: =sum(BL11:BW11) -> 74800 | BY11: =sum(BY4:BY7)*0.34+BY5*0.41 -> 6233.3333 | BZ11: =sum(BZ4:BZ7)*0.34+BZ5*0.41 -> 6233.3333 | CA11: =sum(CA4:CA7)*0.34+CA5*0.41 -> 6233.3333 | CB11: =sum(CB4:CB7)*0.34+CB5*0.41 -> 6233.3333 | CC11: =sum(CC4:CC7)*0.34+CC5*0.41 -> 10200 | CD11: =sum(CD4:CD7)*0.34+CD5*0.41 -> 10200 | CE11: =sum(CE4:CE7)*0.34+CE5*0.41 -> 1710200 | CF11: =sum(CF4:CF7)*0.34+CF5*0.41 -> 1710200 | ... CJ11: =sum(CJ4:CJ7)*0.34+CJ5*0.41 -> 10200 | CK11: =sum(BY11:CJ11) -> 6906533.3 | CL11: =sum(CL4:CL7)*0.34+CL5*0.41 -> 6233.3333 | CM11: =sum(CM4:CM7)*0.34+CM5*0.41 -> 6233.3333 | CN11: =sum(CN4:CN7)*0.34+CN5*0.41 -> 6233.3333 | CO11: =sum(CO4:CO7)*0.34+CO5*0.41 -> 10200 | CP11: =sum(CP4:CP7)*0.34+CP5*0.41 -> 10200 | CQ11: =sum(CQ4:CQ7)*0.34+CQ5*0.41 -> 10200 | CR11: =sum(CR4:CR7)*0.34+CR5*0.41 -> 10200 | CS11: =sum(CS4:CS7)*0.34+CS5*0.41 -> 10200 | ... CW11: =sum(CW4:CW7)*0.34+CW5*0.41 -> 10200 | CX11: =sum(CL11:CW11) -> 110500 | CY11: =sum(CY4:CY7)*0.34+CY5*0.41 -> 11333.333 | CZ11: =sum(CZ4:CZ7)*0.34+CZ5*0.41 -> 11333.333
A12: 401k Contribution | O12: =O4*0.04 -> 400 | P12: =P4*0.04 -> 400 | Q12: =Q4*0.03 -> 307.5 | R12: =R4*0.03 -> 307.5 | S12: =S4*0.03 -> 307.5 | T12: =T4*0.03 -> 307.5 | U12: =U4*0.03 -> 307.5 | V12: =V4*0.03 -> 307.5 | W12: =W4*0.03 -> 307.5 | X12: =X4*0.03 -> 307.5 | Y12: =Y4*0.03 -> 307.5 | Z12: =Z4*0 -> 0 | AA12: =AA4*0 -> 0 | AB12: 0 | AC12: =AC4*0.025 -> 333.33333 | AD12: =AD4*0.004 -> 53.333333 | AE12: =AE4*0.004 -> 53.333333 | AF12: =AF4*0 -> 0 | AG12: =AG4*0 -> 0 | AH12: =AH4*0 -> 0 | AI12: =AI4*0.025 -> 333.33333 | AJ12: =AJ4*0.025 -> 333.33333 | AK12: =AK4*0 -> 0 | AL12: =AL4*0 -> 0 | AM12: =AM4*0 -> 0 | AN12: =AN4*0 -> 0 | AO12: =AO4*0 -> 0 | AP12: =AP4*0 -> 0 | AQ12: =AQ4*0 -> 0 | AR12: =AR4*0 -> 0 | ... BJ12: =BJ4*0 -> 0 | BL12: =BL4*0 -> 0 | BM12: =BM4*0 -> 0 | BN12: =BN4*0 -> 0 | BO12: =BO4*0 -> 0 | BP12: =BP4*0 -> 0 | BQ12: =BQ4*0 -> 0 | BR12: =BR4*0 -> 0 | BS12: =BS4*0 -> 0 | ... BW12: =BW4*0 -> 0 | BX12: =sum(BL12:BW12) -> 0 | BY12: =BY4*0 -> 0 | BZ12: =BZ4*0 -> 0 | CA12: =CA4*0 -> 0 | CB12: =CB4*0 -> 0 | CC12: =CC4*0 -> 0 | CD12: =CD4*0 -> 0 | CE12: =CE4*0 -> 0 | CF12: =CF4*0 -> 0 | ... CJ12: =CJ4*0 -> 0 | CK12: =sum(BY12:CJ12) -> 0 | CL12: =CL4*0 -> 0 | CM12: =CM4*0 -> 0 | CN12: =CN4*0 -> 0 | CO12: =CO4*0 -> 0 | CP12: =CP4*0 -> 0 | CQ12: =CQ4*0 -> 0 | CR12: =CR4*0 -> 0 | CS12: =CS4*0 -> 0 | ... CW12: =CW4*0 -> 0 | CX12: =sum(CL12:CW12) -> 0 | CY12: =CY4*0 -> 0 | CZ12: =CZ4*0 -> 0
A13: Net Take Home | C13: =C10-C11+C5 -> 6200 | D13: =D10-D11+D5 -> 11580 | E13: =E10-E11+E5 -> 6600 | F13: =F10-F11+F5 -> 6600 | G13: =G10-G11+G5 -> 6600 | H13: =H10-H11+H5 -> 6600 | I13: =I10-I11+I5 -> 14900 | J13: =J10-J11+J5 -> 14900 | ... L13: =L10-L11+L5 -> 6600 | M13: =M10-M11 -> 7128 | N13: =N10-N11 -> 6930 | O13: =O4+O7+O5-O11-O12+O8 -> 7200 | P13: =P10-P11-P12 -> 11873 | Q13: =Q10-Q11-Q12 -> 6876.5 | R13: =R10-R11-R12 -> 6657.5 | S13: =S10-S11-S12 -> 9857.5 | T13: =T10-T11-T12 -> 6457.5 | U13: =U10-U11-U12 -> 6457.5 | V13: =V10-V11-V12 -> 6757.5 | W13: =W10-W11-W12 -> 6457.5 | ... BJ13: =BJ10-BJ11-BJ12 -> 12100 | BL13: =BL10-BL11-BL12 -> 42100 | BM13: =BM10-BM11-BM12 -> 22100 | BN13: =BN10-BN11-BN12 -> 37100 | BO13: =BO10-BO11-BO12 -> 36100 | BP13: =BP10-BP11-BP12 -> 14100 | BQ13: =BQ10-BQ11-BQ12 -> 32100 | BR13: =BR10-BR11-BR12 -> 62100 | BS13: =BS10-BS11-BS12 -> 20900 | ... BW13: =BW10-BW11-BW12 -> 22100 | BX13: =sum(BL13:BW13) -> 335000 | BY13: =BY10-BY11-BY12 -> 22100 | BZ13: =BZ10-BZ11-BZ12 -> 22100 | CA13: =CA10-CA11-CA12 -> 97100 | CB13: =CB10-CB11-CB12 -> 105600 | CC13: =CC10-CC11-CC12 -> 19800 | CD13: =CD10-CD11-CD12 -> 269800 | CE13: =CE10-CE11-CE12 -> 3319800 | CF13: =CF10-CF11-CF12 -> 3319800 | ... CJ13: =CJ10-CJ11-CJ12 -> 19800 | CK13: =sum(BY13:CJ13) -> 13855300 | CL13: =CL10-CL11-CL12 -> 22100 | CM13: =CM10-CM11-CM12 -> 22100 | CN13: =CN10-CN11-CN12 -> 40600 | CO13: =CO10-CO11-CO12 -> 219800 | CP13: =CP10-CP11-CP12 -> 19800 | CQ13: =CQ10-CQ11-CQ12 -> 19800 | CR13: =CR10-CR11-CR12 -> 19800 | CS13: =CS10-CS11-CS12 -> 19800 | ... CW13: =CW10-CW11-CW12 -> 19800 | CX13: =sum(CL13:CW13) -> 463000 | CY13: =CY10-CY11-CY12 -> 22000 | CZ13: =CZ10-CZ11-CZ12 -> 22000
A15: Expenses (60%)
A16: Fixed Costs (40%)
A17: Home | B17: Rent | C17: 1450 | D17: 1450 | E17: 1450 | F17: 1450 | G17: 1450 | H17: =1450+350 -> 1800 | I17: =1853+569 -> 2422 | J17: 0 | K17: 1000 | L17: =3383-1500 -> 1883 | M17: =1954 -> 1954 | N17: 1900 | O17: 1900 | P17: 1900 | Q17: 1900 | R17: 1921 | S17: 1921 | T17: =1921 -> 1921 | U17: 120 | V17: =120+700 -> 820 | W17: =sum(120+700) -> 820 | X17: =sum(336,1740) -> 2076 | Y17: =sum(1740) -> 1740 | Z17: 1571.7 | AA17: =sum(1740) -> 1740 | AB17: =sum(1740) -> 1740 | AC17: =sum(1740) -> 1740 | AD17: =sum(1740) -> 1740 | AE17: =sum(1740) -> 1740 | AF17: =sum(1740) -> 1740 | AG17: =sum(1740) -> 1740 | AH17: =sum(4000,1700) -> 5700 | AI17: =sum(2000) -> 2000 | AJ17: =sum(2700) -> 2700 | AK17: =sum(2700) -> 2700 | AL17: =sum(2700) -> 2700 | AM17: =sum(2700) -> 2700 | AN17: =sum(2700) -> 2700 | AO17: =sum(2700) -> 2700 | AP17: =sum(2700) -> 2700 | AQ17: =sum(2700) -> 2700 | ... AT17: =sum(2700) -> 2700 | AU17: =sum(2800) -> 2800 | AV17: =sum(2800) -> 2800 | AW17: =sum(2800) -> 2800 | AX17: =sum(2800) -> 2800 | AY17: =sum(2800) -> 2800 | AZ17: =sum(2800) -> 2800 | BA17: =-sum(2800) -> -2800 | BB17: =-sum(2800) -> -2800 | BC17: =-sum(2800) -> -2800 | BD17: =-sum(2800) -> -2800 | BE17: =-sum(2800) -> -2800 | BF17: =-sum(2800) -> -2800 | BG17: =-sum(2800) -> -2800 | BH17: =-sum(2800) -> -2800 | ... BJ17: =-sum(2800) -> -2800 | BL17: 2800 | BM17: 2800 | BN17: 2800 | BO17: 2800 | BP17: 2800 | BQ17: 2800 | BR17: =sum(2900) -> 2900 | BS17: =sum(2900,4620*2) -> 12140 | BT17: 4620 | BU17: 4620 | BV17: 4620 | BW17: 4620 | BX17: =sum(BL17:BW17) -> 50320 | BY17: 4620 | BZ17: 4620 | CA17: 4620 | CB17: 4620 | CC17: 4620 | CD17: 4620 | CE17: 4620 | CF17: 4620 | CG17: 4620 | CH17: 4620 | CI17: 4620 | CJ17: 4620 | CK17: =sum(BY17:CJ17) -> 55440 | CL17: 4620 | CM17: 4620 | CN17: 4620 | CO17: 4620 | CP17: 4620 | CQ17: 4620 | CR17: 4620 | CS17: 4620 | CT17: 4620 | CU17: 4620 | CV17: 4620 | CW17: 4620 | CX17: =sum(CL17:CW17) -> 55440 | CY17: 4500 | CZ17: 4500
B18: Utilities | I18: 100 | J18: 35 | K18: 90 | L18: =90 -> 90 | M18: 20 | N18: 90 | O18: 90 | P18: 90 | Q18: 90 | R18: 90 | S18: 90 | T18: 90 | U18: 0 | V18: 0 | W18: 0 | X18: 0 | Y18: 90 | Z18: 90 | AA18: 90 | AB18: 90 | AC18: 90 | AD18: 90 | AE18: 90 | AF18: 90 | AG18: 90 | AH18: 90 | AI18: 90 | AJ18: 90 | AK18: 90 | AL18: 90 | AM18: 90 | AN18: 90 | AO18: 90 | AP18: 90 | AQ18: 90 | AR18: 90 | AS18: 90 | AT18: 90 | AU18: 90 | AV18: 90 | AW18: 90 | AX18: 90 | AY18: 90 | AZ18: 90 | BA18: -90 | BB18: -90 | BC18: -90 | BD18: -90 | BE18: -90 | BF18: -90 | BG18: -90 | BH18: -90 | BI18: -90 | BJ18: -90 | BL18: 90 | BM18: 90 | BN18: 90 | BO18: 90 | BP18: 90 | BQ18: 90 | BR18: 90 | BS18: 90 | BT18: 90 | BU18: 120 | BV18: 120 | BW18: 120 | BX18: =sum(BL18:BW18) -> 1170 | BY18: 120 | BZ18: 120 | CA18: 120 | CB18: 120 | CC18: 120 | CD18: 120 | CE18: 120 | CF18: 120 | CG18: 120 | CH18: 120 | CI18: 120 | CJ18: 120 | CK18: =sum(BY18:CJ18) -> 1440 | CL18: 120 | CM18: 120 | CN18: 120 | CO18: 120 | CP18: 120 | CQ18: 120 | CR18: 120 | CS18: 120 | CT18: 120 | CU18: 120 | CV18: 120 | CW18: 120 | CX18: =sum(CL18:CW18) -> 1440 | CY18: 90 | CZ18: 90
B19: Wifi | C19: =62.95/2 -> 31.475 | D19: =62.95/2 -> 31.475 | E19: =62.95/2 -> 31.475 | F19: =62.95/2 -> 31.475 | G19: =62.95/2 -> 31.475 | H19: =62.95/2 -> 31.475 | I19: =62.95/2 -> 31.475 | J19: =62.95/2 -> 31.475 | ... T19: =62.95/2 -> 31.475 | U19: 0 | V19: 0 | W19: 0 | X19: 0 | Y19: =62.95/2 -> 31.475 | Z19: =91/2 -> 45.5 | AA19: =62.95/2 -> 31.475 | AB19: =62.95/2 -> 31.475 | AC19: =62.95/2 -> 31.475 | AD19: =62.95/2 -> 31.475 | AE19: =62.95/2 -> 31.475 | AF19: =62.95/2 -> 31.475 | AG19: =62.95/2 -> 31.475 | AH19: =0 -> 0 | AI19: =100/2 -> 50 | AJ19: =100/2 -> 50 | AK19: =100/2 -> 50 | AL19: =100/2 -> 50 | AM19: =100/2 -> 50 | AN19: =100/2 -> 50 | AO19: =100/2 -> 50 | AP19: =100/2 -> 50 | ... AZ19: =100/2 -> 50 | BA19: =-100/2 -> -50 | BB19: =-100/2 -> -50 | BC19: =-100/2 -> -50 | BD19: =-100/2 -> -50 | BE19: =-100/2 -> -50 | BF19: =-100/2 -> -50 | BG19: =-100/2 -> -50 | BH19: =-100/2 -> -50 | ... BJ19: =-100/2 -> -50 | BL19: 60 | BM19: 60 | BN19: 60 | BO19: 60 | BP19: 60 | BQ19: 60 | BR19: 60 | BS19: 60 | BT19: 60 | BU19: 120 | BV19: 120 | BW19: 120 | BX19: =sum(BL19:BW19) -> 900 | BY19: 120 | BZ19: 120 | CA19: 120 | CB19: 120 | CC19: 120 | CD19: 120 | CE19: 120 | CF19: 120 | CG19: 120 | CH19: 120 | CI19: 120 | CJ19: 120 | CK19: =sum(BY19:CJ19) -> 1440 | CL19: 120 | CM19: 120 | CN19: 120 | CO19: 120 | CP19: 120 | CQ19: 120 | CR19: 120 | CS19: 120 | CT19: 120 | CU19: 120 | CV19: 120 | CW19: 120 | CX19: =sum(CL19:CW19) -> 1440 | CY19: 60 | CZ19: 60
B20: Groceries | I20: 400 | J20: =75*4 -> 300 | K20: =50*4 -> 200 | L20: =55*4 -> 220 | M20: =55*4 -> 220 | N20: =55*4 -> 220 | O20: =55*4 -> 220 | P20: =60*4 -> 240 | Q20: =200+150+250 -> 600 | R20: =195+200+150 -> 545 | S20: =100*4 -> 400 | T20: =60*4 -> 240 | U20: =60*4 -> 240 | V20: =60*4 -> 240 | W20: =60*4 -> 240 | X20: =60*4 -> 240 | Y20: =60*4 -> 240 | Z20: =60*4 -> 240 | AA20: =60*4 -> 240 | ... AJ20: =60*4 -> 240 | AK20: =100*4 -> 400 | AL20: =100*4 -> 400 | AM20: =100*4 -> 400 | AN20: =100*4 -> 400 | AO20: =100*4 -> 400 | AP20: =100*4 -> 400 | AQ20: =100*4 -> 400 | AR20: =100*4 -> 400 | ... AZ20: =100*4 -> 400 | BA20: =-100*4 -> -400 | BB20: =-100*4 -> -400 | BC20: =-100*4 -> -400 | BD20: =-100*4 -> -400 | BE20: =-100*4 -> -400 | BF20: =-100*4 -> -400 | BG20: =-100*4 -> -400 | BH20: =-100*4 -> -400 | ... BJ20: =-100*4 -> -400 | BL20: 500 | BM20: 500 | BN20: 500 | BO20: 500 | BP20: 500 | BQ20: 500 | BR20: 500 | BS20: 500 | BT20: 500 | BU20: 500 | BV20: 500 | BW20: 500 | BX20: =sum(BL20:BW20) -> 6000 | BY20: 500 | BZ20: 500 | CA20: 500 | CB20: 500 | CC20: 500 | CD20: 500 | CE20: 500 | CF20: 500 | CG20: 500 | CH20: 500 | CI20: 500 | CJ20: 500 | CK20: =sum(BY20:CJ20) -> 6000 | CL20: 500 | CM20: 500 | CN20: 500 | CO20: 500 | CP20: 500 | CQ20: 500 | CR20: 500 | CS20: 500 | CT20: 500 | CU20: 500 | CV20: 500 | CW20: 500 | CX20: =sum(CL20:CW20) -> 6000 | CY20: 500 | CZ20: 500
A21: Phone | B21: Phone Bill | E21: 100 | F21: 128.79 | G21: 120 | H21: =120+500 -> 620 | I21: 120.64 | J21: 120.64 | K21: 120.64 | L21: 150 | M21: 120.64 | N21: 120.64 | O21: 120 | P21: 120 | Q21: 120 | R21: 120 | S21: 120 | T21: 120 | U21: 120 | V21: 120 | W21: 120 | X21: 120 | Y21: 150 | Z21: 185.09 | AA21: 185.09 | AB21: 185.09 | AC21: 185.09 | AD21: 185.09 | AE21: 185.09 | AF21: 185.09 | AG21: 185.09 | AH21: 185.09 | AI21: 185.09 | AJ21: 185.09 | AK21: 0 | AL21: 0 | AM21: 0 | AN21: 0 | AO21: 0 | AP21: 0 | AQ21: 0 | AR21: 0 | AS21: 0 | AT21: 0 | AU21: 0 | AV21: 0 | AW21: 150 | AX21: 150 | AY21: 150 | AZ21: 150 | BA21: -150 | BB21: -150 | BC21: -150 | BD21: -150 | BE21: -150 | BF21: -150 | BG21: -150 | BH21: -150 | BI21: -150 | BJ21: -150 | BL21: 150 | BM21: 150 | BN21: 150 | BO21: 150 | BP21: 150 | BQ21: 150 | BR21: 150 | BS21: 150 | BT21: 150 | BU21: 300 | BV21: 300 | BW21: 300 | BX21: =sum(BL21:BW21) -> 2250 | BY21: 150 | BZ21: 150 | CA21: 150 | CB21: 150 | CC21: 150 | CD21: 150 | CE21: 150 | CF21: 150 | CG21: 150 | CH21: 150 | CI21: 150 | CJ21: 150 | CK21: =sum(BY21:CJ21) -> 1800 | CL21: 150 | CM21: 150 | CN21: 150 | CO21: 150 | CP21: 150 | CQ21: 150 | CR21: 150 | CS21: 150 | CT21: 150 | CU21: 150 | CV21: 150 | CW21: 150 | CX21: =sum(CL21:CW21) -> 1800 | CY21: 0 | CZ21: 0
A22: Car | B22: Car | N22: 0 | O22: 0 | P22: 0 | Q22: 0 | R22: 0 | S22: 0 | T22: 200 | U22: 0 | V22: =sum(116,60,300,300) -> 776 | W22: =sum(343,60,75) -> 478 | X22: =sum(343,180,150) -> 673 | Y22: =sum(343,180,100) -> 623 | Z22: =sum(343,180,100) -> 623 | AA22: =sum(343,180,100) -> 623 | AB22: =sum(343,180,100) -> 623 | AC22: =sum(343,180,100) -> 623 | AD22: =sum(343,180,100) -> 623 | AE22: =sum(343,180,100) -> 623 | AF22: =sum(343,180,100) -> 623 | ... AH22: =sum(343,180,100) -> 623 | AI22: 400 | AJ22: 0 | AK22: 0 | AL22: 175 | AM22: 0 | AN22: 0 | AO22: 0 | AP22: 0 | AQ22: 0 | AR22: 0 | AS22: 0 | AT22: 0 | AU22: 0 | AV22: 0 | AW22: 0 | AX22: 0 | AY22: 0 | AZ22: 0 | BA22: 0 | BB22: 0 | BC22: 0 | BD22: 0 | BE22: 0 | BF22: 0 | BG22: 0 | BH22: 0 | BI22: -150 | BJ22: -300 | BL22: 0 | BM22: 0 | BN22: 0 | BO22: 0 | BP22: 0 | BQ22: 0 | BR22: 0 | BS22: 0 | BT22: 0 | BU22: 0 | BV22: 0 | BW22: 0 | BX22: =sum(BL22:BW22) -> 0 | BY22: 0 | BZ22: 0 | CA22: 0 | CB22: 0 | CC22: 0 | CD22: 0 | CE22: 0 | CF22: 0 | CG22: 0 | CH22: 0 | CI22: 0 | CJ22: 0 | CK22: =sum(BY22:CJ22) -> 0 | CL22: 0 | CM22: 0 | CN22: 0 | CO22: 0 | CP22: 0 | CQ22: 0 | CR22: 0 | CS22: 0 | CT22: 0 | CU22: 0 | CV22: 0 | CW22: 0 | CX22: =sum(CL22:CW22) -> 0 | CY22: 0 | CZ22: 0
A23: Transportation | B23: Ridesharing | J23: =170*4-20 -> 660 | K23: =22*7*4 -> 616 | L23: =22*7*4 -> 616 | M23: =20*4*4 -> 320 | N23: =20*4*4 -> 320 | O23: =15*7*4 -> 420 | P23: =15*30 -> 450 | Q23: =15*5 -> 75 | R23: =10*4 -> 40 | S23: =10*4 -> 40 | T23: =10*20 -> 200 | U23: =10*10 -> 100 | V23: 0 | W23: 0 | X23: 25 | Y23: 25 | Z23: 25 | AA23: 25 | AB23: 25 | AC23: 25 | AD23: 25 | AE23: 25 | AF23: 25 | AG23: 25 | AH23: 100 | AI23: 200 | AJ23: 100 | AK23: 100 | AL23: 100 | AM23: 100 | AN23: 100 | AO23: 100 | AP23: 100 | AQ23: 100 | AR23: 100 | AS23: 100 | AT23: 100 | AU23: 100 | AV23: 100 | AW23: 100 | AX23: 100 | AY23: 100 | AZ23: 100 | BA23: -100 | BB23: -100 | BC23: -100 | BD23: -100 | BE23: -200 | BF23: -200 | BG23: -200 | BH23: -200 | BI23: -200 | BJ23: -200 | BL23: =sum(20*3*4) -> 240 | BM23: =sum(20*3*4) -> 240 | BN23: =sum(20*3*4) -> 240 | BO23: =sum(20*3*4) -> 240 | BP23: =sum(20*3*4) -> 240 | BQ23: =sum(20*3*4) -> 240 | BR23: =sum(20*3*4) -> 240 | BS23: =sum(20*3*4) -> 240 | ... BW23: =sum(20*3*4) -> 240 | BX23: =sum(BL23:BW23) -> 2880 | BY23: =sum(20*3*4) -> 240 | BZ23: =sum(20*3*4) -> 240 | CA23: =sum(20*3*4) -> 240 | CB23: =sum(20*3*4) -> 240 | CC23: =sum(20*3*4) -> 240 | CD23: =sum(20*3*4) -> 240 | CE23: =sum(20*3*4) -> 240 | CF23: =sum(20*3*4) -> 240 | ... CJ23: =sum(20*3*4) -> 240 | CK23: =sum(BY23:CJ23) -> 2880 | CL23: =sum(20*3*4) -> 240 | CM23: =sum(20*3*4) -> 240 | CN23: =sum(20*3*4) -> 240 | CO23: =sum(20*3*4) -> 240 | CP23: =sum(20*3*4) -> 240 | CQ23: =sum(20*3*4) -> 240 | CR23: =sum(20*3*4) -> 240 | CS23: =sum(20*3*4) -> 240 | ... CW23: =sum(20*3*4) -> 240 | CX23: =sum(CL23:CW23) -> 2880 | CY23: =sum(20*3*4) -> 240 | CZ23: =sum(20*3*4) -> 240
B24: Metro | C24: 200 | D24: 200 | E24: 100 | F24: 200 | G24: 200 | H24: 200 | I24: =8*4*4+20*4 -> 208 | J24: =8*7*4 -> 224 | K24: =8*4*4 -> 128 | L24: =8*7*4 -> 224 | M24: =8*4*4 -> 128 | N24: =8*5*4 -> 160 | O24: =8*7*4 -> 224 | P24: =8*5*4 -> 160 | Q24: =40 -> 40 | R24: =0 -> 0 | S24: =0 -> 0 | T24: 0 | U24: 0 | V24: 0 | W24: 0 | X24: 0 | Y24: 0 | Z24: 0 | AA24: 0 | AB24: 0 | AC24: 0 | AD24: 0 | AE24: 0 | AF24: 0 | AG24: 0 | AH24: 50 | AI24: 50 | AJ24: 50 | AK24: 50 | AL24: 50 | AM24: 25 | AN24: 25 | AO24: 25 | AP24: 50 | AQ24: 50 | AR24: 50 | AS24: 50 | AT24: 50 | AU24: 50 | AV24: 50 | AW24: 50 | AX24: 50 | AY24: 50 | AZ24: 50 | BA24: -50 | BB24: -50 | BC24: -50 | BD24: -50 | BE24: -50 | BF24: -50 | BG24: -50 | BH24: -50 | BI24: -50 | BJ24: -50 | BL24: =sum(3*8*4) -> 96 | BM24: =sum(3*8*4) -> 96 | BN24: =sum(3*8*4) -> 96 | BO24: =sum(3*8*4) -> 96 | BP24: =sum(3*8*4) -> 96 | BQ24: =sum(3*8*4) -> 96 | BR24: =sum(3*8*4) -> 96 | BS24: =sum(3*8*4) -> 96 | ... BW24: =sum(3*8*4) -> 96 | BX24: =sum(BL24:BW24) -> 1152 | BY24: =sum(3*8*4) -> 96 | BZ24: =sum(3*8*4) -> 96 | CA24: =sum(3*8*4) -> 96 | CB24: =sum(3*8*4) -> 96 | CC24: =sum(3*8*4) -> 96 | CD24: =sum(3*8*4) -> 96 | CE24: =sum(3*8*4) -> 96 | CF24: =sum(3*8*4) -> 96 | ... CJ24: =sum(3*8*4) -> 96 | CK24: =sum(BY24:CJ24) -> 1152 | CL24: =sum(3*8*4) -> 96 | CM24: =sum(3*8*4) -> 96 | CN24: =sum(3*8*4) -> 96 | CO24: =sum(3*8*4) -> 96 | CP24: =sum(3*8*4) -> 96 | CQ24: =sum(3*8*4) -> 96 | CR24: =sum(3*8*4) -> 96 | CS24: =sum(3*8*4) -> 96 | ... CW24: =sum(3*8*4) -> 96 | CX24: =sum(CL24:CW24) -> 1152 | CY24: =sum(3*8*4) -> 96 | CZ24: =sum(3*8*4) -> 96
P25: =sum(P17:P24)/P13 -> 0.25195612 | Q25: =sum(Q17:Q24)/Q13 -> 0.41539664 | R25: =sum(R17:R24)/R13 -> 0.4126887 | S25: =sum(S17:S24)/S13 -> 0.26400964 | T25: =sum(T17:T24)/T13 -> 0.43398761 | U25: =sum(U17:U24)/U13 -> 0.089818041 | V25: =sum(V17:V24)/V13 -> 0.28945616 | W25: =sum(W17:W24)/W13 -> 0.25675571 | ... AZ25: =sum(AZ17:AZ24)/AZ13 -> 0.13212341
A26: Variable Costs (20%)
A27: Guilt Free | B27: Safe to Spend - Weekdays | C27: 1150 | D27: 1000 | E27: 1000 | F27: 1120 | G27: 1000 | H27: 500 | I27: =160*4 -> 640 | J27: =125*4 -> 500 | K27: =25*7*4 -> 700 | L27: =50*7*4 -> 1400 | M27: =25*7*4 -> 700 | N27: 1500 | O27: =30*5*4 -> 600 | P27: =30*20 -> 600 | Q27: =20*10 -> 200 | R27: =10*20 -> 200 | S27: =5*20 -> 100 | T27: =20*20 -> 400 | U27: =15*20 -> 300 | V27: =15*20 -> 300 | W27: =15*20 -> 300 | X27: =15*20 -> 300 | Y27: =50*20 -> 1000 | Z27: =45*20 -> 900 | AA27: =25*20 -> 500 | AB27: =25*20 -> 500 | AC27: =45*20 -> 900 | AD27: =25*20 -> 500 | AE27: =25*20 -> 500 | AF27: =25*20 -> 500 | AG27: =25*20 -> 500 | AH27: =25*20 -> 500 | AI27: =45*20 -> 900 | AJ27: =45*20 -> 900 | AK27: =45*20 -> 900 | AL27: =75*20 -> 1500 | AM27: =75*20 -> 1500 | AN27: =75*20 -> 1500 | AO27: =75*20 -> 1500 | AP27: =150*20 -> 3000 | AQ27: =75*20 -> 1500 | AR27: =75*20 -> 1500 | AS27: =75*20 -> 1500 | AT27: =75*20 -> 1500 | AU27: =75*20 -> 1500 | AV27: =75*20 -> 1500 | AW27: =75*20 -> 1500 | AX27: =75*20 -> 1500 | ... AZ27: =75*20 -> 1500 | BA27: =-75*20 -> -1500 | BB27: =-75*20 -> -1500 | BC27: =-75*20 -> -1500 | BD27: =-75*20 -> -1500 | BE27: =-75*20 -> -1500 | BF27: =-75*20 -> -1500 | BG27: =-75*20 -> -1500 | BH27: =-75*20 -> -1500 | ... BJ27: =-75*20 -> -1500 | BL27: =125*20 -> 2500 | BM27: =125*20 -> 2500 | BN27: =125*20 -> 2500 | BO27: =125*20 -> 2500 | BP27: =125*20 -> 2500 | BQ27: =125*20 -> 2500 | BR27: =125*20 -> 2500 | BS27: =125*20 -> 2500 | BT27: =125*20 -> 2500 | BU27: =75*20 -> 1500 | BV27: =75*20 -> 1500 | BW27: =125*20 -> 2500 | BX27: =sum(BL27:BW27) -> 28000 | BY27: =125*20 -> 2500 | BZ27: =125*20 -> 2500 | CA27: =125*20 -> 2500 | CB27: =125*20 -> 2500 | CC27: =125*20 -> 2500 | CD27: =125*20 -> 2500 | CE27: =125*20 -> 2500 | CF27: =125*20 -> 2500 | ... CJ27: =125*20 -> 2500 | CK27: =sum(BY27:CJ27) -> 30000 | CL27: =125*20 -> 2500 | CM27: =125*20 -> 2500 | CN27: =125*20 -> 2500 | CO27: =125*20 -> 2500 | CP27: =125*20 -> 2500 | CQ27: =125*20 -> 2500 | CR27: =125*20 -> 2500 | CS27: =125*20 -> 2500 | ... CW27: =125*20 -> 2500 | CX27: =sum(CL27:CW27) -> 30000 | CY27: =125*20 -> 2500 | CZ27: =125*20 -> 2500
B28: Safe to Spend - Weekends | I28: =100*4 -> 400 | J28: =200*4 -> 800 | K28: =50*2*2*4 -> 800 | L28: =50*2*2*4 -> 800 | M28: =40*2*4 -> 320 | N28: =50*2*4 -> 400 | O28: =50*2*4 -> 400 | P28: =100*4 -> 400 | Q28: =45*2 -> 90 | R28: =20*8 -> 160 | S28: =30*8 -> 240 | T28: =45*8 -> 360 | U28: =20*8 -> 160 | V28: =45*8 -> 360 | W28: =40*8 -> 320 | X28: =40*8 -> 320 | Y28: =100*8 -> 800 | Z28: =100*8 -> 800 | AA28: =100*8 -> 800 | AB28: =100*8+300 -> 1100 | AC28: =100*8 -> 800 | AD28: =75*8 -> 600 | AE28: =75*8 -> 600 | AF28: =75*8 -> 600 | AG28: =75*8 -> 600 | AH28: =75*8 -> 600 | AI28: =100*10 -> 1000 | AJ28: =100*8 -> 800 | AK28: =100*8 -> 800 | AL28: =100*8 -> 800 | AM28: =100*8 -> 800 | AN28: =100*8 -> 800 | AO28: =100*8 -> 800 | AP28: =150*8 -> 1200 | AQ28: =100*8 -> 800 | AR28: =100*8 -> 800 | AS28: =100*8 -> 800 | AT28: =100*8 -> 800 | AU28: =100*8 -> 800 | AV28: =100*8 -> 800 | AW28: =100*8 -> 800 | AX28: =100*8 -> 800 | ... AZ28: =100*8 -> 800 | BA28: =-100*8 -> -800 | BB28: =-100*8 -> -800 | BC28: =-100*8 -> -800 | BD28: =-100*8 -> -800 | BE28: =-100*8 -> -800 | BF28: =-100*8 -> -800 | BG28: =-100*8 -> -800 | BH28: =-100*8 -> -800 | ... BJ28: =-100*8 -> -800 | BL28: =200*8 -> 1600 | BM28: =200*8 -> 1600 | BN28: =200*8 -> 1600 | BO28: =200*8 -> 1600 | BP28: =200*8 -> 1600 | BQ28: =200*8 -> 1600 | BR28: =200*8 -> 1600 | BS28: =200*8 -> 1600 | BT28: =200*8 -> 1600 | BU28: =100*8 -> 800 | BV28: =100*8 -> 800 | BW28: =200*8 -> 1600 | BX28: =sum(BL28:BW28) -> 17600 | BY28: =200*8 -> 1600 | BZ28: =200*8 -> 1600 | CA28: =200*8 -> 1600 | CB28: =200*8 -> 1600 | CC28: =200*8 -> 1600 | CD28: =200*8 -> 1600 | CE28: =200*8 -> 1600 | CF28: =200*8 -> 1600 | ... CJ28: =200*8 -> 1600 | CK28: =sum(BY28:CJ28) -> 19200 | CL28: =200*8 -> 1600 | CM28: =200*8 -> 1600 | CN28: =200*8 -> 1600 | CO28: =200*8 -> 1600 | CP28: =200*8 -> 1600 | CQ28: =200*8 -> 1600 | CR28: =200*8 -> 1600 | CS28: =200*8 -> 1600 | ... CW28: =200*8 -> 1600 | CX28: =sum(CL28:CW28) -> 19200 | CY28: =200*8 -> 1600 | CZ28: =200*8 -> 1600
B29: Entertainment | C29: 0 | D29: 0 | E29: 0 | F29: 0 | G29: 0 | H29: 0 | I29: 0 | J29: 0 | K29: 0 | L29: 0 | M29: 0 | N29: 200 | O29: 400 | P29: 0 | Q29: 0 | R29: 0 | S29: 0 | T29: 0 | U29: 0 | V29: 0 | W29: 0 | X29: 0 | Y29: 0 | Z29: 0 | AA29: 0 | AB29: 0 | AC29: 0 | AD29: 0 | AE29: 0 | AF29: 0 | AG29: 0 | AH29: 0 | AI29: 0 | AJ29: 0 | AK29: 0 | AL29: 0 | AM29: 0 | AN29: 0 | AO29: 0 | AP29: 0 | AQ29: 0 | AR29: 0 | AS29: 0 | AT29: 0 | AU29: 0 | AV29: 0 | AW29: 200 | AX29: 200 | AY29: 200 | AZ29: 200 | BA29: -200 | BB29: -200 | BC29: -200 | BD29: -200 | BE29: -200 | BF29: -200 | BG29: -200 | BH29: -200 | BI29: -200 | BJ29: -200 | BL29: 200 | BM29: 200 | BN29: =sum(200,4000) -> 4200 | BO29: 200 | BP29: 200 | BQ29: =sum(200,2000) -> 2200 | BR29: 200 | BS29: 200 | BT29: 200 | BU29: 200 | BV29: 200 | BW29: 200 | BX29: =sum(BL29:BW29) -> 8400 | BY29: 200 | BZ29: 200 | CA29: 200 | CB29: 200 | CC29: 200 | CD29: 200 | CE29: 200 | CF29: 200 | CG29: 200 | CH29: 200 | CI29: 200 | CJ29: 200 | CK29: =sum(BY29:CJ29) -> 2400 | CL29: 200 | CM29: 200 | CN29: 200 | CO29: 200 | CP29: 200 | CQ29: 200 | CR29: 200 | CS29: 200 | CT29: 200 | CU29: 200 | CV29: 200 | CW29: 200 | CX29: =sum(CL29:CW29) -> 2400 | CY29: 200 | CZ29: 200
B30: Subscriptions | C30: 10 | D30: 10 | E30: 10 | F30: 10 | G30: =10+5+20 -> 35 | H30: =10+5+20 -> 35 | I30: =10+20+60 -> 90 | J30: =10+20+30+15 -> 75 | K30: =10+5+20+30 -> 65 | L30: =10+5+20+60 -> 95 | M30: =10+5+20+60 -> 95 | N30: =10+5+20+60 -> 95 | O30: =10+5+20+60 -> 95 | P30: =10+5+20+60+4+4 -> 103 | Q30: =10+5+20+60+35.68 -> 130.68 | R30: =10+5+20+60 -> 95 | S30: =10+13+20+60 -> 103 | T30: =10+13+20+60 -> 103 | U30: =10+13+20+60 -> 103 | V30: =sum(10,13,20,60,4,15,20) -> 142 | W30: =sum(10,13,20,60,4,15,70) -> 192 | X30: =sum(10,13,20,60,4,15,0) -> 122 | Y30: =sum(10,13,20,60,4,15,0) -> 122 | Z30: =sum(10,13,60,4,15,0) -> 102 | AA30: =sum(10,13,60,4,15,0) -> 102 | AB30: =sum(10,13,60,4,15,0) -> 102 | AC30: =sum(10,13,60,4,15,0) -> 102 | AD30: =sum(10,13,60,4,15,0) -> 102 | AE30: =sum(10,13,60,4,15,0) -> 102 | AF30: =sum(10,13,60,4,15,0) -> 102 | AG30: =sum(10,13,60,4,15,0) -> 102 | ... AZ30: =sum(10,13,60,4,15,0) -> 102 | BA30: =-sum(10,13,60,4,15,0) -> -102 | BB30: =-sum(10,13,60,4,15,0) -> -102 | BC30: =-sum(10,13,60,4,15,0) -> -102 | BD30: =-sum(10,13,60,4,15,0) -> -102 | BE30: =-sum(10,13,60,4,15,0) -> -102 | BF30: =-sum(10,13,60,4,15,0) -> -102 | BG30: =-sum(10,13,60,4,15,0) -> -102 | BH30: =-sum(10,13,60,4,15,0) -> -102 | ... BJ30: =-sum(10,13,60,4,15,0) -> -102 | BL30: =sum(10,13,60,4,15,0) -> 102 | BM30: =sum(10,13,60,4,15,0) -> 102 | BN30: =sum(10,13,60,4,15,0) -> 102 | BO30: =sum(10,13,60,4,15,0) -> 102 | BP30: =sum(10,13,60,4,15,0) -> 102 | BQ30: =sum(10,13,60,4,15,0) -> 102 | BR30: =sum(10,13,60,4,15,0) -> 102 | BS30: =sum(10,13,60,4,15,0) -> 102 | ... BW30: =sum(10,13,60,4,15,0) -> 102 | BX30: =sum(BL30:BW30) -> 1224 | BY30: =sum(10,13,60,4,15,0) -> 102 | BZ30: =sum(10,13,60,4,15,0) -> 102 | CA30: =sum(10,13,60,4,15,0) -> 102 | CB30: =sum(10,13,60,4,15,0) -> 102 | CC30: =sum(10,13,60,4,15,0) -> 102 | CD30: =sum(10,13,60,4,15,0) -> 102 | CE30: =sum(10,13,60,4,15,0) -> 102 | CF30: =sum(10,13,60,4,15,0) -> 102 | ... CJ30: =sum(10,13,60,4,15,0) -> 102 | CK30: =sum(BY30:CJ30) -> 1224 | CL30: =sum(10,13,60,4,15,0) -> 102 | CM30: =sum(10,13,60,4,15,0) -> 102 | CN30: =sum(10,13,60,4,15,0) -> 102 | CO30: =sum(10,13,60,4,15,0) -> 102 | CP30: =sum(10,13,60,4,15,0) -> 102 | CQ30: =sum(10,13,60,4,15,0) -> 102 | CR30: =sum(10,13,60,4,15,0) -> 102 | CS30: =sum(10,13,60,4,15,0) -> 102 | ... CW30: =sum(10,13,60,4,15,0) -> 102 | CX30: =sum(CL30:CW30) -> 1224 | CY30: =sum(10,13,60,4,15,0) -> 102 | CZ30: =sum(10,13,60,4,15,0) -> 102
B31: Travel | C31: 0 | D31: 0 | E31: 500 | F31: 500 | G31: 0 | H31: 0 | I31: 0 | J31: 500 | K31: 450 | L31: 300 | M31: 200 | N31: 100 | O31: 0 | P31: =250+179 -> 429 | Q31: 0 | R31: =260*2 -> 520 | S31: 0 | T31: =sum(500/2,185,25,84,257) -> 801 | U31: =sum(270,250) -> 520 | V31: =sum(300,600,240) -> 1140 | W31: =375+74 -> 449 | X31: 0 | Y31: 0 | Z31: =sum(548.5,400,55.1,92.1,169.66,100) -> 1365.36 | AA31: ='Travel Expenses - Tulum'!C32-Z31 -> 2256.425 | AB31: 90 | AC31: 1200 | AD31: 0 | AE31: 500 | AF31: 0 | AG31: 0 | AH31: 0 | AI31: 0 | AJ31: 0 | AK31: 0 | AL31: =1500+600 -> 2100 | AM31: 0 | AN31: 0 | AO31: 0 | AP31: 0 | AQ31: 0 | AR31: 0 | AS31: 0 | AT31: 0 | AU31: 0 | AV31: 0 | AW31: 0 | AX31: 0 | AY31: 0 | AZ31: =sum(650,375,300) -> 1325 | BA31: 0 | BB31: 0 | BC31: =-1700 -> -1700 | BD31: =-sum(3000,4396) -> -7396 | BE31: 0 | BF31: 300 | BG31: 0 | BH31: 0 | BI31: 0 | BJ31: -1000 | BL31: 20000 | BM31: 0 | BN31: =sum(3000,1200) -> 4200 | BO31: 0 | BP31: 0 | BQ31: =sum(4000,600) -> 4600 | BR31: 0 | BS31: =sum(2000,6200,2500) -> 10700 | BT31: =sum(1000) -> 1000 | BU31: 0 | BV31: 0 | BW31: 2000 | BX31: =sum(BL31:BW31) -> 42500 | BY31: 5000 | BZ31: 0 | CA31: 0 | CB31: 0 | CC31: 0 | CD31: 5000 | CE31: 0 | CF31: 0 | CG31: 0 | CH31: 0 | CI31: 0 | CJ31: 0 | CK31: =sum(BY31:CJ31) -> 10000 | CL31: 5000 | CM31: 0 | CN31: 0 | CO31: 0 | CP31: 0 | CQ31: 5000 | CR31: 0 | CS31: 0 | CT31: 0 | CU31: 0 | CV31: 0 | CW31: 0 | CX31: =sum(CL31:CW31) -> 10000 | CY31: 0 | CZ31: 0
A32: Home | B32: Home Goods | I32: 600 | J32: 0 | K32: 0 | L32: 0 | M32: 0 | N32: 0 | O32: 0 | P32: =43+83 -> 126 | Q32: =90+266+80 -> 436 | R32: 0 | S32: 0 | T32: 0 | U32: 0 | V32: 0 | W32: 0 | X32: 1000 | Y32: 0 | Z32: =sum(250,100,250) -> 600 | AA32: 0 | AB32: 0 | AC32: 0 | AD32: 0 | AE32: 0 | AF32: 0 | AG32: 0 | AH32: 2000 | AI32: 0 | AJ32: 0 | AK32: 0 | AL32: 25 | AM32: 0 | AN32: 0 | AO32: 0 | AP32: 0 | AQ32: 0 | AR32: 0 | AS32: 0 | AT32: 0 | AU32: 0 | AV32: 0 | AW32: 50 | AX32: 50 | AY32: 50 | AZ32: 50 | BA32: -50 | BB32: -50 | BC32: -50 | BD32: 0 | BE32: 0 | BF32: -50 | BG32: =sum(-50,-500) -> -550 | BH32: -50 | BI32: -50 | BJ32: -50 | BL32: 500 | BM32: 0 | BN32: 1000 | BO32: 500 | BP32: 500 | BQ32: 500 | BR32: 1000 | BS32: =sum(2500,2000,1000) -> 5500 | BT32: =1200 -> 1200 | BU32: 100 | BV32: 100 | BW32: 100 | BX32: =sum(BL32:BW32) -> 11000 | BY32: 250 | BZ32: 250 | CA32: 250 | CB32: 250 | CC32: 250 | CD32: 250 | CE32: 250 | CF32: 250 | CG32: 250 | CH32: 250 | CI32: 250 | CJ32: 250 | CK32: =sum(BY32:CJ32) -> 3000 | CL32: 250 | CM32: 250 | CN32: 250 | CO32: 250 | CP32: 250 | CQ32: 250 | CR32: 250 | CS32: 250 | CT32: 250 | CU32: 250 | CV32: 250 | CW32: 250 | CX32: =sum(CL32:CW32) -> 3000 | CY32: 250 | CZ32: 250
B33: Books | I33: 10 | J33: 0 | K33: =12*2 -> 24 | L33: 0 | M33: 0 | N33: =12*1 -> 12 | O33: =12*1 -> 12 | P33: =13 -> 13 | Q33: 0 | R33: =12*1 -> 12 | S33: =12*1 -> 12 | T33: =12*1 -> 12 | U33: =12*1 -> 12 | V33: =12*1 -> 12 | W33: =12*1 -> 12 | X33: =12*1 -> 12 | Y33: =12*1 -> 12 | ... AJ33: =12*1 -> 12 | AK33: 0 | AL33: 0 | AM33: =12*1 -> 12 | AN33: =12*1 -> 12 | AO33: =12*1 -> 12 | AP33: =12*1 -> 12 | AQ33: =12*1 -> 12 | AR33: =12*1 -> 12 | AS33: 50 | AT33: =12*1 -> 12 | AU33: =12*1 -> 12 | AV33: =12*1 -> 12 | AW33: =12*1 -> 12 | AX33: =12*1 -> 12 | AY33: =12*1 -> 12 | AZ33: =12*1 -> 12 | BA33: =-20*1 -> -20 | BB33: =-20*1 -> -20 | BC33: =-20*1 -> -20 | BD33: =-20*1 -> -20 | BE33: =-20*1 -> -20 | BF33: =-20*1 -> -20 | BG33: =-20*1 -> -20 | BH33: =-20*1 -> -20 | ... BJ33: =-20*1 -> -20 | BL33: 20 | BM33: 20 | BN33: 20 | BO33: 20 | BP33: 20 | BQ33: 20 | BR33: 20 | BS33: 20 | BT33: 20 | BU33: 20 | BV33: 20 | BW33: 20 | BX33: =sum(BL33:BW33) -> 240 | BY33: 20 | BZ33: 20 | CA33: 20 | CB33: 20 | CC33: 20 | CD33: 20 | CE33: 20 | CF33: 20 | CG33: 20 | CH33: 20 | CI33: 20 | CJ33: 20 | CK33: =sum(BY33:CJ33) -> 240 | CL33: 20 | CM33: 20 | CN33: 20 | CO33: 20 | CP33: 20 | CQ33: 20 | CR33: 20 | CS33: 20 | CT33: 20 | CU33: 20 | CV33: 20 | CW33: 20 | CX33: =sum(CL33:CW33) -> 240 | CY33: 20 | CZ33: 20
B34: Clothing | I34: 100 | J34: 60 | K34: 250 | L34: 0 | M34: 50 | N34: 0 | O34: 100 | P34: 0 | Q34: 0 | R34: 0 | S34: 0 | T34: 300 | U34: 100 | V34: 100 | W34: 100 | X34: 100 | Y34: 100 | Z34: 100 | AA34: 100 | AB34: 100 | AC34: 100 | AD34: 100 | AE34: 100 | AF34: 100 | AG34: 100 | AH34: 100 | AI34: 100 | AJ34: 100 | AK34: 100 | AL34: 300 | AM34: 300 | AN34: 300 | AO34: 300 | AP34: 300 | AQ34: 300 | AR34: 300 | AS34: 300 | AT34: 300 | AU34: 300 | AV34: 300 | AW34: 300 | AX34: 300 | AY34: 300 | AZ34: 300 | BA34: -500 | BB34: -500 | BC34: -500 | BD34: -500 | BE34: -500 | BF34: -200 | BG34: -500 | BH34: -500 | BI34: -500 | BJ34: -500 | BL34: 750 | BM34: 500 | BN34: 1000 | BO34: 700 | BP34: 2000 | BQ34: 500 | BR34: 500 | BS34: 3000 | BT34: 500 | BU34: 100 | BV34: 100 | BW34: 500 | BX34: =sum(BL34:BW34) -> 10150 | BY34: 500 | BZ34: 500 | CA34: 5000 | CB34: 500 | CC34: 500 | CD34: 500 | CE34: 500 | CF34: 500 | CG34: 500 | CH34: 500 | CI34: 500 | CJ34: 500 | CK34: =sum(BY34:CJ34) -> 10500 | CL34: 500 | CM34: 500 | CN34: 500 | CO34: 500 | CP34: 500 | CQ34: 500 | CR34: 500 | CS34: 500 | CT34: 500 | CU34: 500 | CV34: 500 | CW34: 500 | CX34: =sum(CL34:CW34) -> 6000 | CY34: 500 | CZ34: 500
A35: Health | B35: Dental | C35: 0 | D35: 0 | E35: 0 | F35: 0 | G35: 0 | H35: 0 | I35: 25 | J35: 0 | K35: 0 | L35: 0 | M35: 0 | N35: 0 | O35: 0 | P35: 0 | Q35: 0 | R35: 0 | S35: 0 | T35: 0 | U35: 0 | V35: 0 | W35: 0 | X35: 0 | Y35: 0 | Z35: 0 | AA35: 0 | AB35: 0 | AC35: 0 | AD35: 0 | AE35: 0 | AF35: 0 | AG35: 0 | AH35: 0 | AI35: 0 | AJ35: 0 | AK35: 0 | AL35: 0 | AM35: 0 | AN35: 0 | AO35: 0 | AP35: 0 | AQ35: 0 | AR35: 0 | AS35: 0 | AT35: 0 | AU35: 0 | AV35: 0 | AW35: 0 | AX35: 0 | AY35: 0 | AZ35: 0 | BA35: 0 | BB35: 0 | BC35: 0 | BD35: 0 | BE35: 0 | BF35: 0 | BG35: 0 | BH35: 0 | BI35: 0 | BJ35: 0 | BL35: 0 | BM35: 0 | BN35: 1000 | BO35: 2000 | BP35: 0 | BQ35: 0 | BR35: 0 | BS35: 0 | BT35: 0 | BU35: 0 | BV35: 0 | BW35: 0 | BX35: =sum(BL35:BW35) -> 3000 | BY35: 0 | BZ35: 0 | CA35: 200 | CB35: 200 | CC35: 200 | CD35: 200 | CE35: 200 | CF35: 200 | CG35: 200 | CH35: 200 | CI35: 0 | CJ35: 0 | CK35: =sum(BY35:CJ35) -> 1600 | CL35: 0 | CM35: 0 | CN35: 1000 | CO35: 2000 | CP35: 0 | CQ35: 0 | CR35: 0 | CS35: 0 | CT35: 0 | CU35: 0 | CV35: 0 | CW35: 0 | CX35: =sum(CL35:CW35) -> 3000 | CY35: 0 | CZ35: 0
B36: Healthcare | J36: 0 | K36: 0 | L36: 0 | M36: 0 | N36: 0 | O36: 0 | P36: 0 | Q36: 0 | R36: 0 | S36: 0 | T36: 0 | U36: 0 | V36: =490 -> 490 | W36: 0 | X36: 0 | Y36: 0 | Z36: 0 | AA36: 0 | AB36: 0 | AC36: 0 | AD36: 0 | AE36: 0 | AF36: 0 | AG36: 0 | AH36: 0 | AI36: 0 | AJ36: 0 | AK36: 250 | AL36: 0 | AM36: 0 | AN36: 0 | AO36: 0 | AP36: 0 | AQ36: 0 | AR36: 0 | AS36: 0 | AT36: 0 | AU36: 0 | AV36: 0 | AW36: 0 | AX36: 0 | AY36: 0 | AZ36: 0 | BA36: 0 | BB36: 0 | BC36: 0 | BD36: 0 | BE36: 0 | BF36: 0 | BG36: 0 | BH36: 0 | BI36: 0 | BJ36: 0 | BL36: 0 | BM36: 0 | BN36: 0 | BO36: 0 | BP36: 0 | BQ36: 0 | BR36: 0 | BS36: 0 | BT36: 0 | BU36: 0 | BV36: 0 | BW36: 0 | BX36: =sum(BL36:BW36) -> 0 | BY36: 0 | BZ36: 0 | CA36: 0 | CB36: 0 | CC36: 0 | CD36: 0 | CE36: 0 | CF36: 0 | CG36: 0 | CH36: 0 | CI36: 0 | CJ36: 0 | CK36: =sum(BY36:CJ36) -> 0 | CL36: 0 | CM36: 0 | CN36: 0 | CO36: 0 | CP36: 0 | CQ36: 0 | CR36: 0 | CS36: 0 | CT36: 0 | CU36: 0 | CV36: 0 | CW36: 0 | CX36: =sum(CL36:CW36) -> 0 | CY36: 0 | CZ36: 0
B37: Self-Care | I37: 100 | J37: =60+20+350 -> 430 | K37: 50 | L37: 60 | M37: 60 | N37: 95 | O37: 100 | P37: 100 | Q37: 60 | R37: 0 | S37: 0 | T37: 100 | U37: 50 | V37: 100 | W37: 100 | X37: 100 | Y37: 100 | Z37: 100 | AA37: 100 | AB37: 100 | AC37: 100 | AD37: 100 | AE37: 100 | AF37: 100 | AG37: 100 | AH37: 100 | AI37: 100 | AJ37: 100 | AK37: 100 | AL37: 100 | AM37: 100 | AN37: 100 | AO37: 100 | AP37: 100 | AQ37: 100 | AR37: 100 | AS37: 100 | AT37: 100 | AU37: 100 | AV37: 100 | AW37: 100 | AX37: 100 | AY37: 100 | AZ37: 100 | BA37: -100 | BB37: -100 | BC37: -100 | BD37: -100 | BE37: -100 | BF37: -100 | BG37: -100 | BH37: -100 | BI37: -100 | BJ37: -100 | BL37: 200 | BM37: 200 | BN37: 500 | BO37: 500 | BP37: 500 | BQ37: 500 | BR37: 500 | BS37: 500 | BT37: 500 | BU37: =sum(300,300*2) -> 900 | BV37: =sum(300,300*4) -> 1500 | BW37: =sum(300,300*2) -> 900 | BX37: =sum(BL37:BW37) -> 7200 | BY37: =sum(300,400,400,2700) -> 3800 | BZ37: =sum(300,400,400) -> 1100 | CA37: =sum(300,400,400) -> 1100 | CB37: =sum(300,400,400) -> 1100 | CC37: =sum(300,400,400) -> 1100 | CD37: =sum(300,400,400) -> 1100 | CE37: =sum(300,400,400) -> 1100 | CF37: =sum(300,400,400) -> 1100 | CG37: =sum(300,400,400) -> 1100 | ... CJ37: =sum(300,400,400) -> 1100 | CK37: =sum(BY37:CJ37) -> 15900 | CL37: =sum(300,400,400) -> 1100 | CM37: =sum(300,400,400) -> 1100 | CN37: =sum(300,400,400) -> 1100 | CO37: =sum(300,400,400) -> 1100 | CP37: =sum(300,400,400) -> 1100 | CQ37: =sum(300,400,400) -> 1100 | CR37: =sum(300,400,400) -> 1100 | CS37: =sum(300,400,400) -> 1100 | ... CW37: =sum(300,400,400) -> 1100 | CX37: =sum(CL37:CW37) -> 13200 | CY37: 500 | CZ37: 500
B38: Gym | C38: 0 | D38: 0 | E38: 0 | F38: 0 | G38: 0 | H38: 0 | I38: 0 | J38: 0 | K38: 0 | L38: 0 | M38: 0 | N38: 0 | O38: 0 | P38: 0 | Q38: 0 | R38: 0 | S38: 0 | T38: 0 | U38: 0 | V38: 0 | W38: 0 | X38: 0 | Y38: 0 | Z38: 0 | AA38: 0 | AB38: 0 | AC38: 0 | AD38: 0 | AE38: 0 | AF38: 0 | AG38: 0 | AH38: 100 | AI38: 300 | AJ38: 100 | AK38: 175 | AL38: 175 | AM38: 175 | AN38: 175 | AO38: 175 | AP38: 175 | AQ38: 175 | AR38: 175 | AS38: 175 | AT38: 175 | AU38: 175 | AV38: 175 | AW38: 175 | AX38: 175 | AY38: 175 | AZ38: 175 | BA38: -175 | BB38: -175 | BC38: -175 | BD38: -175 | BE38: =sum(-175,-1200) -> -1375 | BF38: =sum(-175) -> -175 | BG38: =sum(-175,-185) -> -360 | BH38: =sum(-175) -> -175 | BI38: =sum(-175) -> -175 | BJ38: =sum(-175,-800/2) -> -575 | BL38: 175 | BM38: =sum(175,1600) -> 1775 | BN38: 175 | BO38: 175 | BP38: 175 | BQ38: =sum(400,600) -> 1000 | BR38: =sum(600,600) -> 1200 | BS38: =sum(600,600) -> 1200 | BT38: =sum(600,600) -> 1200 | BU38: =sum(600,600) -> 1200 | BV38: =sum(600,600) -> 1200 | BW38: =sum(600,300) -> 900 | BX38: =sum(BL38:BW38) -> 10375 | BY38: =sum(600,600) -> 1200 | BZ38: =sum(600,600) -> 1200 | CA38: =sum(600,600) -> 1200 | CB38: =sum(600,600) -> 1200 | CC38: =sum(600,600) -> 1200 | CD38: =sum(600,600) -> 1200 | CE38: =sum(600,600) -> 1200 | CF38: =sum(600,600) -> 1200 | ... CJ38: =sum(600,600) -> 1200 | CK38: =sum(BY38:CJ38) -> 14400 | CL38: =sum(600,600) -> 1200 | CM38: =sum(600,600) -> 1200 | CN38: =sum(600,600) -> 1200 | CO38: =sum(600,600) -> 1200 | CP38: =sum(600,600) -> 1200 | CQ38: =sum(600,600) -> 1200 | CR38: =sum(600,600) -> 1200 | CS38: =sum(600,600) -> 1200 | ... CW38: =sum(600,600) -> 1200 | CX38: =sum(CL38:CW38) -> 14400 | CY38: 175 | CZ38: 175
A39: Misc | B39: Dog Stuff | E39: 50 | F39: 50 | G39: 50 | H39: 50 | I39: 100 | J39: =30+40 -> 70 | K39: 0 | L39: 50 | M39: 50 | N39: 20 | O39: 0 | P39: 50 | Q39: 30 | R39: =15+35 -> 50 | S39: 10 | T39: 40 | U39: 30 | V39: =sum(30,100) -> 130 | W39: 30 | X39: 30 | Y39: 30 | Z39: 10 | AA39: 10 | AB39: 10 | AC39: 10 | AD39: 10 | AE39: 10 | AF39: 10 | AG39: 10 | AH39: 10 | AI39: 10 | AJ39: 10 | AK39: 10 | AL39: 10 | AM39: 10 | AN39: 10 | AO39: 10 | AP39: 10 | AQ39: 10 | AR39: 10 | AS39: 0 | AT39: 10 | AU39: 10 | AV39: 10 | AW39: 30 | AX39: 30 | AY39: 30 | AZ39: 30 | BA39: -30 | BB39: -30 | BC39: -30 | BD39: =sum(-30,-50) -> -80 | BE39: =sum(-30,-50) -> -80 | BF39: =sum(-30,-50) -> -80 | BG39: =sum(-30,-50) -> -80 | BH39: =sum(-30,-50) -> -80 | BI39: =sum(-30,-50) -> -80 | BJ39: =sum(-30,-50) -> -80 | BL39: 100 | BM39: 100 | BN39: 100 | BO39: 100 | BP39: 100 | BQ39: =sum(500,100) -> 600 | BR39: 100 | BS39: 100 | BT39: 100 | BU39: 100 | BV39: 100 | BW39: 100 | BX39: =sum(BL39:BW39) -> 1700 | BY39: 100 | BZ39: 100 | CA39: 100 | CB39: 100 | CC39: 100 | CD39: =sum(500,100) -> 600 | CE39: 100 | CF39: 100 | CG39: 100 | CH39: 100 | CI39: 100 | CJ39: 100 | CK39: =sum(BY39:CJ39) -> 1700 | CL39: 100 | CM39: 100 | CN39: 100 | CO39: 100 | CP39: 100 | CQ39: =sum(500,100) -> 600 | CR39: 100 | CS39: 100 | CT39: 100 | CU39: 100 | CV39: 100 | CW39: 100 | CX39: =sum(CL39:CW39) -> 1700 | CY39: 100 | CZ39: 100
B40: Contractor Services | K40: 0 | L40: 0 | M40: 0 | N40: 250 | O40: 0 | P40: 200 | Q40: 0 | R40: 0 | S40: =0 -> 0 | T40: =840+450 -> 1290 | U40: 0 | V40: 0 | W40: 0 | X40: 0 | Y40: 0 | Z40: 0 | AA40: 0 | AB40: 0 | AC40: 0 | AD40: 0 | AE40: 0 | AF40: 0 | AG40: 0 | AH40: 0 | AI40: 0 | AJ40: 0 | AK40: 0 | AL40: 0 | AM40: 0 | AN40: 0 | AO40: 0 | AP40: 0 | AQ40: 0 | AR40: 0 | AS40: 0 | AT40: 0 | AU40: 0 | AV40: 0 | AW40: 0 | AX40: 0 | AY40: 0 | AZ40: 0 | BA40: 0 | BB40: 0 | BC40: 0 | BD40: 0 | BE40: 0 | BF40: 0 | BG40: 0 | BH40: 0 | BI40: 0 | BJ40: 0 | BL40: 0 | BM40: 0 | BN40: 0 | BO40: 0 | BP40: 0 | BQ40: 0 | BR40: 0 | BS40: 0 | BT40: 0 | BU40: 0 | BV40: 0 | BW40: 0 | BX40: =sum(BL40:BW40) -> 0 | BY40: 0 | BZ40: 0 | CA40: 0 | CB40: 0 | CC40: 0 | CD40: 0 | CE40: 0 | CF40: 0 | CG40: 0 | CH40: 0 | CI40: 0 | CJ40: 0 | CK40: =sum(BY40:CJ40) -> 0 | CL40: 0 | CM40: 0 | CN40: 0 | CO40: 0 | CP40: 0 | CQ40: 0 | CR40: 0 | CS40: 0 | CT40: 0 | CU40: 0 | CV40: 0 | CW40: 0 | CX40: =sum(CL40:CW40) -> 0 | CY40: 0 | CZ40: 0
B41: Tech | X41: =272+375 -> 647 | Y41: 0 | Z41: 0 | AA41: 0 | AB41: 0 | AC41: 0 | AD41: 0 | AE41: 0 | AF41: 0 | AG41: 0 | AH41: 0 | AI41: 0 | AJ41: 0 | AK41: 0 | AL41: 0 | AM41: 0 | AN41: 0 | AO41: 0 | AP41: 0 | AQ41: 0 | AR41: 0 | AS41: 0 | AT41: 0 | AU41: 0 | AV41: 0 | AW41: 0 | AX41: 0 | AY41: 0 | AZ41: 0 | BA41: 0 | BB41: 0 | BC41: 0 | BD41: 0 | BE41: 0 | BF41: 0 | BG41: 0 | BH41: 0 | BI41: 0 | BJ41: 0 | BL41: 0 | BM41: 0 | BN41: 0 | BO41: 0 | BP41: 0 | BQ41: 0 | BR41: 0 | BS41: 0 | BT41: 0 | BU41: 0 | BV41: 0 | BW41: 0 | BX41: =sum(BL41:BW41) -> 0 | BY41: 0 | BZ41: 0 | CA41: 0 | CB41: 0 | CC41: 0 | CD41: 0 | CE41: 0 | CF41: 0 | CG41: 0 | CH41: 0 | CI41: 0 | CJ41: 0 | CK41: =sum(BY41:CJ41) -> 0 | CL41: 0 | CM41: 0 | CN41: 0 | CO41: 0 | CP41: 0 | CQ41: 0 | CR41: 0 | CS41: 0 | CT41: 0 | CU41: 0 | CV41: 0 | CW41: 0 | CX41: =sum(CL41:CW41) -> 0 | CY41: 0 | CZ41: 0
B42: Misc. | T42: 0 | U42: 0 | V42: 0 | W42: 0 | X42: =sum(700/2,50,500) -> 900 | Y42: 0 | Z42: 0 | AA42: 0 | AB42: 0 | AC42: 0 | AD42: 0 | AE42: 0 | AF42: 0 | AG42: 0 | AH42: 0 | AI42: 0 | AJ42: 0 | AK42: 0 | AL42: 1500 | AM42: 0 | AN42: 0 | AO42: 0 | AP42: 0 | AQ42: 0 | AR42: 0 | AS42: 0 | AT42: 0 | AU42: 0 | AV42: 0 | AW42: 0 | AX42: 500 | AY42: 0 | AZ42: 0 | BA42: 0 | BB42: 0 | BC42: 0 | BD42: 0 | BE42: 0 | BF42: 0 | BG42: 0 | BH42: 0 | BI42: 0 | BJ42: -3500 | BL42: 3500 | BM42: 2000 | BN42: =2000 -> 2000 | BO42: 700 | BP42: 0 | BQ42: 0 | BR42: 0 | BS42: =sum(3500,1850,1000,200) -> 6550 | BT42: 0 | BU42: 1000 | BV42: 0 | BW42: 1500 | BX42: =sum(BL42:BW42) -> 17250 | BY42: 0 | BZ42: 0 | CA42: =sum(7500,5000) -> 12500 | CB42: 2500 | CC42: 0 | CD42: =sum(30000,2500) -> 32500 | CE42: 0 | CF42: 0 | CG42: 0 | CH42: 0 | CI42: 0 | CJ42: 0 | CK42: =sum(BY42:CJ42) -> 47500 | CL42: 0 | CM42: 0 | CN42: 0 | CO42: 30000 | CP42: 0 | CQ42: 0 | CR42: 0 | CS42: 0 | CT42: 0 | CU42: 0 | CV42: 0 | CW42: 0 | CX42: =sum(CL42:CW42) -> 30000 | CY42: 0 | CZ42: 0
...

Sheet PRO FORMA
A1: Matt Wright
A2: Pro-Forma FY '23-'25
I3: 2023 | J3: 2024 | K3: 2025 | L3: Projected
B4: 2024 | C4: 2025 | D4: 2026 | E4: 2027 | F4: 2028 | G4: 2029 | H4: 2030 | I4: PROJECTED | J4: PROJECTED | K4: PROJECTED | L4: Total 2022
A5: OPERATING REVENUE
A6: Salary - Consensys | B6: =212000/2 -> 106000 | C6: =220000/2 -> 110000 | D6: =sum(500000/12*6) -> 250000 | E6: =sum(500000/12*6) -> 250000 | F6: =sum(500000/12*6) -> 250000 | G6: =sum(500000/12*6) -> 250000 | I6: =sum(C6*2) -> 220000 | J6: =sum(D6:E6) -> 500000 | K6: =sum(F6:G6) -> 500000 | L6: =#REF!+I6 -> #REF!
A7: Salary - EVM Capital | B7: 0 | C7: =sum(500000/12*6) -> 250000 | D7: =sum(500000/12*6) -> 250000 | E7: =sum(500000/12*6) -> 250000 | F7: =sum(500000/12*6) -> 250000 | G7: =sum(500000/12*6) -> 250000 | I7: =sum(C7*2) -> 500000 | J7: =sum(D7:E7) -> 500000 | K7: =sum(F7:G7) -> 500000
A8: Consulting | B8: 0 | C8: 0 | D8: =sum(250000/12*6) -> 125000 | E8: =sum(250000/12*6*3) -> 375000 | F8: =sum(250000/12*6*3) -> 375000 | G8: =sum(250000/12*6*3) -> 375000 | I8: =sum(C8*2) -> 0 | J8: =sum(D8:E8) -> 500000 | K8: =sum(F8:G8) -> 750000
B9: 0 | C9: 0 | D9: =sum(20000*6) -> 120000 | E9: =sum(20000*6) -> 120000 | F9: =sum(20000*6) -> 120000 | G9: =sum(20000*6) -> 120000 | I9: =sum(C9*2) -> 0 | J9: =sum(D9:E9) -> 240000 | K9: =sum(F9:G9) -> 240000
A11: Total Revenue | B11: =sum(B6:B10) -> 106000 | C11: =sum(C6:C10) -> 360000 | D11: =sum(D6:D10) -> 745000 | E11: =sum(E6:E10) -> 995000 | F11: =sum(F6:F10) -> 995000 | G11: =sum(G6:G10) -> 995000 | I11: =sum(I6:I10) -> 720000 | J11: =sum(J6:J10) -> 1740000 | K11: =sum(K6:K10) -> 1990000
A13: OPERATING EXPENSES
A14: FTE Payroll | B14: =sum('BUDGET FY''23'!B16:G16) -> #REF! | C14: =sum('BUDGET FY''23'!H16:M16) -> #REF! | D14: =sum(-200000/2,-200000/2,-165000/2) -> -282500 | E14: =sum(-200000/2,-200000/2,-165000/2) -> -282500 | F14: =sum(-200000/2,-200000/2,-165000/2) -> -282500 | G14: =sum(-200000/2,-200000/2,-165000/2) -> -282500 | I14: =sum(C14*2) -> #REF! | J14: =sum(D14:E14) -> -565000 | K14: =sum(F14:G14) -> -565000
A15: Contractors | B15: =sum('BUDGET FY''23'!B17:G17) -> #REF! | C15: =sum('BUDGET FY''23'!H17:M17) -> #REF! | D15: =sum(-10000*2,-5000*2) -> -30000 | E15: =sum(-10000*2,-5000*2) -> -30000 | F15: =sum(-10000*2,-5000*2) -> -30000 | G15: =sum(-10000*2,-5000*2) -> -30000 | I15: =sum(C15*2) -> #REF! | J15: =sum(D15:E15) -> -60000 | K15: =sum(F15:G15) -> -60000
A16: Legal, Accounting | B16: =sum('BUDGET FY''23'!B18:G18) -> #REF! | C16: =sum('BUDGET FY''23'!H18:M18) -> #REF! | D16: =-50000 -> -50000 | E16: =-50000 -> -50000 | F16: =-50000 -> -50000 | G16: =-50000 -> -50000 | I16: =sum(C16*2) -> #REF! | J16: =sum(D16:E16) -> -100000 | K16: =sum(F16:G16) -> -100000 | L16: =#REF!+I16 -> #REF!
A17: Office | B17: =sum('BUDGET FY''23'!B19:G19) -> #REF! | C17: =sum('BUDGET FY''23'!H19:M19) -> #REF! | D17: 0 | E17: 0 | F17: 0 | G17: 0 | I17: =sum(C17*2) -> #REF! | J17: =sum(D17:E17) -> 0 | K17: =sum(F17:G17) -> 0 | L17: =#REF!+I17 -> #REF!
A18: Rent | B18: =sum('BUDGET FY''23'!B20:G20) -> #REF! | C18: =sum('BUDGET FY''23'!H20:M20) -> #REF! | D18: =sum(-1400*6) -> -8400 | E18: =sum(-1400*6) -> -8400 | F18: =sum(-1400*6) -> -8400 | G18: =sum(-1400*6) -> -8400 | I18: =sum(C18*2) -> #REF! | J18: =sum(D18:E18) -> -16800 | K18: =sum(F18:G18) -> -16800 | L18: =#REF!+I18 -> #REF!
A19: Utilities | B19: =sum('BUDGET FY''23'!B21:G21) -> #REF! | C19: =sum('BUDGET FY''23'!H21:M21) -> #REF! | D19: =sum(-1000*6) -> -6000 | E19: =sum(-1000*6) -> -6000 | F19: =sum(-1000*6) -> -6000 | G19: =sum(-1000*6) -> -6000 | I19: =sum(C19*2) -> #REF! | J19: =sum(D19:E19) -> -12000 | K19: =sum(F19:G19) -> -12000 | L19: =#REF!+I19 -> #REF!
A20: Software & Apps | B20: =sum('BUDGET FY''23'!B22:G22) -> #REF! | C20: =sum('BUDGET FY''23'!H22:M22) -> #REF! | D20: =sum(-500*6) -> -3000 | E20: =sum(-500*6) -> -3000 | F20: =sum(-500*6) -> -3000 | G20: =sum(-500*6) -> -3000 | I20: =sum(C20*2) -> #REF! | J20: =sum(D20:E20) -> -6000 | K20: =sum(F20:G20) -> -6000 | L20: =#REF!+I20 -> #REF!
A21: Travel | B21: =sum('BUDGET FY''23'!B23:G23) -> #REF! | C21: =sum('BUDGET FY''23'!H23:M23) -> #REF! | D21: =sum(-5000*6) -> -30000 | E21: =sum(-5000*6) -> -30000 | F21: =sum(-5000*6) -> -30000 | G21: =sum(-5000*6) -> -30000 | I21: =sum(C21*2) -> #REF! | J21: =sum(D21:E21) -> -60000 | K21: =sum(F21:G21) -> -60000 | L21: =#REF!+I21 -> #REF!
A22: Business Development | B22: =sum('BUDGET FY''23'!B24:G24) -> #REF! | C22: =sum('BUDGET FY''23'!H24:M24) -> #REF! | D22: =sum(-5000*6) -> -30000 | E22: =sum(-5000*6) -> -30000 | F22: =sum(-5000*6) -> -30000 | G22: =sum(-5000*6) -> -30000 | I22: =sum(C22*2) -> #REF! | J22: =sum(D22:E22) -> -60000 | K22: =sum(F22:G22) -> -60000 | L22: =#REF!+I22 -> #REF!
A23: Marketing, Events | B23: =sum('BUDGET FY''23'!B25:G25) -> #REF! | C23: =sum('BUDGET FY''23'!H25:M25) -> #REF! | D23: =sum(-10000*6) -> -60000 | E23: =sum(-10000*6) -> -60000 | F23: =sum(-10000*6) -> -60000 | G23: =sum(-10000*6) -> -60000 | I23: =sum(C23*2) -> #REF! | J23: =sum(D23:E23) -> -120000 | K23: =sum(F23:G23) -> -120000 | L23: =#REF!+I23 -> #REF!
A24: Platform (EVM Labs) | B24: =sum('BUDGET FY''23'!B26:G26) -> #REF! | C24: =sum('BUDGET FY''23'!H26:M26) -> #REF! | D24: 0 | E24: 0 | F24: 0 | G24: 0 | I24: =sum(C24*2) -> #REF! | J24: =sum(D24:E24) -> 0 | K24: =sum(F24:G24) -> 0 | L24: =#REF!+I24 -> #REF!
A25: Bank Fees / Credit Interest | B25: =sum('BUDGET FY''23'!B27:G27) -> #REF! | C25: =sum('BUDGET FY''23'!H27:M27) -> #REF! | D25: 0 | E25: 0 | F25: 0 | G25: 0 | I25: =sum(C25*2) -> #REF! | J25: =sum(D25:E25) -> 0 | K25: =sum(F25:G25) -> 0 | L25: =#REF!+I25 -> #REF!
